package mrhid6.xorbo.worldgen;
import java.util.Random;

import mrhid6.xorbo.blocks.ModBlocks;
import net.minecraft.block.Block;
import net.minecraft.world.World;
import net.minecraft.world.gen.feature.WorldGenerator;

public class SurfaceGenFactory extends WorldGenerator
{

	private int width = 24;
	private int height = 16;
	private int depth = 24;
	protected int[] GetValidSpawnBlocks() {
		return new int[] {
				Block.grass.blockID,
				Block.dirt.blockID
		};
	}

	protected void clearAreaFirst(World world,int i, int j, int k){

		for(int x =i+1;x<(i+width);x++ ){
			for(int z=k+1;z<(k+depth);z++ ){
				for(int y =j;y<(j+height);y++ ){
					world.setBlock(x,y,z, 0);
				}
			}
		}
	}

	public boolean LocationIsValidSpawn(World world, int i, int j, int k){
		int distanceToAir = 0;
		int checkID = world.getBlockId(i, j, k);

		while (checkID != 0){
			distanceToAir++;
			checkID = world.getBlockId(i, j + distanceToAir, k);
		}

		if (distanceToAir > 5){
			return false;
		}
		j += distanceToAir - 1;

		int blockID = world.getBlockId(i, j, k);
		int blockIDAbove = world.getBlockId(i, j+1, k);
		int blockIDBelow = world.getBlockId(i, j-1, k);
		for (int x : GetValidSpawnBlocks()){
			if (blockIDAbove != 0){
				return false;
			}
			if (blockID == x){
				return true;
			}else if (blockID == Block.snow.blockID && blockIDBelow == x){
				return true;
			}
		}
		return false;
	}

	public SurfaceGenFactory() { }

	public boolean generate(World world, Random rand, int i, int j, int k) {
		//check that each corner is one of the valid spawn blocks
		if(!LocationIsValidSpawn(world, i, j, k) || !LocationIsValidSpawn(world, i + 23, j, k) || !LocationIsValidSpawn(world, i + 23, j, k + 22) || !LocationIsValidSpawn(world, i, j, k + 22))
		{
			return false;
		}
		System.out.println("spawned factory");
		
		this.clearAreaFirst(world, i, j, k);
		j--;
		world.setBlock(i + 0, j + 0, k + 0, Block.grass.blockID);
		world.setBlock(i + 0, j + 0, k + 1, Block.grass.blockID);
		world.setBlock(i + 0, j + 0, k + 2, Block.grass.blockID);
		world.setBlock(i + 0, j + 0, k + 3, Block.grass.blockID);
		world.setBlock(i + 0, j + 0, k + 4, Block.grass.blockID);
		world.setBlock(i + 0, j + 0, k + 5, Block.grass.blockID);
		world.setBlock(i + 0, j + 0, k + 6, Block.grass.blockID);
		world.setBlock(i + 0, j + 0, k + 7, Block.grass.blockID);
		world.setBlock(i + 0, j + 0, k + 8, Block.grass.blockID);
		world.setBlock(i + 0, j + 0, k + 9, Block.grass.blockID);
		world.setBlock(i + 0, j + 0, k + 10, Block.grass.blockID);
		world.setBlock(i + 0, j + 0, k + 11, Block.grass.blockID);
		world.setBlock(i + 0, j + 0, k + 12, Block.grass.blockID);
		world.setBlock(i + 0, j + 0, k + 13, Block.grass.blockID);
		world.setBlock(i + 0, j + 0, k + 14, Block.grass.blockID);
		world.setBlock(i + 0, j + 0, k + 15, Block.grass.blockID);
		world.setBlock(i + 0, j + 0, k + 16, Block.grass.blockID);
		world.setBlock(i + 0, j + 0, k + 17, Block.grass.blockID);
		world.setBlock(i + 0, j + 0, k + 18, Block.grass.blockID);
		world.setBlock(i + 0, j + 0, k + 19, Block.grass.blockID);
		world.setBlock(i + 0, j + 0, k + 20, Block.grass.blockID);
		world.setBlock(i + 0, j + 0, k + 21, Block.grass.blockID);
		world.setBlock(i + 0, j + 0, k + 22, Block.grass.blockID);
		world.setBlock(i + 0, j + 0, k + 23, Block.grass.blockID);
		world.setBlock(i + 0, j + 0, k + 24, Block.grass.blockID);
		world.setBlock(i + 1, j + 0, k + 0, Block.grass.blockID);
		world.setBlock(i + 1, j + 0, k + 1, Block.dirt.blockID);
		world.setBlock(i + 1, j + 0, k + 2, Block.dirt.blockID);
		world.setBlock(i + 1, j + 0, k + 3, Block.dirt.blockID);
		world.setBlock(i + 1, j + 0, k + 4, Block.dirt.blockID);
		world.setBlock(i + 1, j + 0, k + 5, Block.dirt.blockID);
		world.setBlock(i + 1, j + 0, k + 6, Block.dirt.blockID);
		world.setBlock(i + 1, j + 0, k + 7, Block.dirt.blockID);
		world.setBlock(i + 1, j + 0, k + 8, Block.dirt.blockID);
		world.setBlock(i + 1, j + 0, k + 9, Block.dirt.blockID);
		world.setBlock(i + 1, j + 0, k + 10, Block.dirt.blockID);
		world.setBlock(i + 1, j + 0, k + 11, Block.dirt.blockID);
		world.setBlock(i + 1, j + 0, k + 12, Block.dirt.blockID);
		world.setBlock(i + 1, j + 0, k + 13, Block.dirt.blockID);
		world.setBlock(i + 1, j + 0, k + 14, Block.dirt.blockID);
		world.setBlock(i + 1, j + 0, k + 15, Block.dirt.blockID);
		world.setBlock(i + 1, j + 0, k + 16, Block.dirt.blockID);
		world.setBlock(i + 1, j + 0, k + 17, Block.dirt.blockID);
		world.setBlock(i + 1, j + 0, k + 18, Block.dirt.blockID);
		world.setBlock(i + 1, j + 0, k + 19, Block.dirt.blockID);
		world.setBlock(i + 1, j + 0, k + 20, Block.dirt.blockID);
		world.setBlock(i + 1, j + 0, k + 21, Block.grass.blockID);
		world.setBlock(i + 1, j + 0, k + 22, Block.grass.blockID);
		world.setBlock(i + 1, j + 0, k + 23, Block.grass.blockID);
		world.setBlock(i + 1, j + 0, k + 24, Block.grass.blockID);
		world.setBlock(i + 1, j + 1, k + 1, Block.stoneBrick.blockID);
		world.setBlock(i + 1, j + 1, k + 2, Block.stoneBrick.blockID);
		world.setBlock(i + 1, j + 1, k + 3, Block.stoneBrick.blockID);
		world.setBlock(i + 1, j + 1, k + 4, Block.stoneBrick.blockID);
		world.setBlock(i + 1, j + 1, k + 5, Block.stoneBrick.blockID);
		world.setBlock(i + 1, j + 1, k + 6, Block.stoneBrick.blockID);
		world.setBlock(i + 1, j + 1, k + 7, Block.stoneBrick.blockID);
		world.setBlock(i + 1, j + 1, k + 8, Block.stoneBrick.blockID);
		world.setBlock(i + 1, j + 1, k + 9, Block.stoneBrick.blockID);
		world.setBlock(i + 1, j + 1, k + 10, Block.stoneBrick.blockID);
		world.setBlock(i + 1, j + 1, k + 11, Block.stoneBrick.blockID);
		world.setBlock(i + 1, j + 1, k + 12, Block.stoneBrick.blockID);
		world.setBlock(i + 1, j + 1, k + 13, Block.stoneBrick.blockID);
		world.setBlock(i + 1, j + 1, k + 14, Block.stoneBrick.blockID);
		world.setBlock(i + 1, j + 1, k + 15, Block.stoneBrick.blockID);
		world.setBlock(i + 1, j + 1, k + 16, Block.stoneBrick.blockID);
		world.setBlock(i + 1, j + 1, k + 17, Block.stoneBrick.blockID);
		world.setBlock(i + 1, j + 1, k + 18, Block.cobblestone.blockID);
		world.setBlock(i + 1, j + 1, k + 19, Block.cobblestone.blockID);
		world.setBlock(i + 1, j + 1, k + 20, Block.cobblestone.blockID);
		world.setBlock(i + 1, j + 2, k + 1, Block.brick.blockID);
		world.setBlock(i + 1, j + 2, k + 2, Block.brick.blockID);
		world.setBlock(i + 1, j + 2, k + 3, Block.brick.blockID);
		world.setBlock(i + 1, j + 2, k + 4, Block.brick.blockID);
		world.setBlock(i + 1, j + 2, k + 5, Block.brick.blockID);
		world.setBlock(i + 1, j + 2, k + 6, Block.brick.blockID);
		world.setBlock(i + 1, j + 2, k + 7, Block.brick.blockID);
		world.setBlock(i + 1, j + 2, k + 8, Block.brick.blockID);
		world.setBlock(i + 1, j + 2, k + 9, Block.brick.blockID);
		world.setBlock(i + 1, j + 2, k + 10, Block.brick.blockID);
		world.setBlock(i + 1, j + 2, k + 11, Block.brick.blockID);
		world.setBlock(i + 1, j + 2, k + 13, Block.fenceIron.blockID);
		world.setBlock(i + 1, j + 2, k + 14, Block.brick.blockID);
		world.setBlock(i + 1, j + 2, k + 15, Block.brick.blockID);
		world.setBlock(i + 1, j + 2, k + 16, Block.brick.blockID);
		world.setBlock(i + 1, j + 2, k + 17, Block.brick.blockID);
		world.setBlock(i + 1, j + 2, k + 18, Block.cobblestone.blockID);
		world.setBlock(i + 1, j + 2, k + 19, Block.cobblestone.blockID);
		world.setBlock(i + 1, j + 2, k + 20, Block.cobblestone.blockID);
		world.setBlock(i + 1, j + 3, k + 1, Block.brick.blockID);
		world.setBlock(i + 1, j + 3, k + 2, Block.brick.blockID);
		world.setBlock(i + 1, j + 3, k + 3, Block.brick.blockID);
		world.setBlock(i + 1, j + 3, k + 4, Block.brick.blockID);
		world.setBlock(i + 1, j + 3, k + 5, Block.brick.blockID);
		world.setBlock(i + 1, j + 3, k + 6, Block.brick.blockID);
		world.setBlock(i + 1, j + 3, k + 7, Block.brick.blockID);
		world.setBlock(i + 1, j + 3, k + 8, Block.brick.blockID);
		world.setBlock(i + 1, j + 3, k + 9, Block.brick.blockID);
		world.setBlock(i + 1, j + 3, k + 10, Block.brick.blockID);
		world.setBlock(i + 1, j + 3, k + 11, Block.brick.blockID);
		world.setBlock(i + 1, j + 3, k + 12, Block.brick.blockID);
		world.setBlock(i + 1, j + 3, k + 13, Block.fenceIron.blockID);
		world.setBlock(i + 1, j + 3, k + 14, Block.brick.blockID);
		world.setBlock(i + 1, j + 3, k + 15, Block.brick.blockID);
		world.setBlock(i + 1, j + 3, k + 16, Block.brick.blockID);
		world.setBlock(i + 1, j + 3, k + 17, Block.brick.blockID);
		world.setBlock(i + 1, j + 3, k + 18, Block.cobblestone.blockID);
		world.setBlock(i + 1, j + 3, k + 19, Block.cobblestone.blockID);
		world.setBlock(i + 1, j + 3, k + 20, Block.cobblestone.blockID);
		world.setBlock(i + 1, j + 4, k + 1, Block.brick.blockID);
		world.setBlock(i + 1, j + 4, k + 2, Block.brick.blockID);
		world.setBlock(i + 1, j + 4, k + 3, Block.brick.blockID);
		world.setBlock(i + 1, j + 4, k + 4, Block.brick.blockID);
		world.setBlock(i + 1, j + 4, k + 5, Block.brick.blockID);
		world.setBlock(i + 1, j + 4, k + 6, Block.brick.blockID);
		world.setBlock(i + 1, j + 4, k + 7, Block.brick.blockID);
		world.setBlock(i + 1, j + 4, k + 8, Block.brick.blockID);
		world.setBlock(i + 1, j + 4, k + 10, Block.fenceIron.blockID);
		world.setBlock(i + 1, j + 4, k + 11, Block.brick.blockID);
		world.setBlock(i + 1, j + 4, k + 12, Block.brick.blockID);
		world.setBlock(i + 1, j + 4, k + 13, Block.brick.blockID);
		world.setBlock(i + 1, j + 4, k + 14, Block.brick.blockID);
		world.setBlock(i + 1, j + 4, k + 15, Block.brick.blockID);
		world.setBlock(i + 1, j + 4, k + 16, Block.brick.blockID);
		world.setBlock(i + 1, j + 4, k + 17, Block.brick.blockID);
		world.setBlock(i + 1, j + 4, k + 18, Block.cobblestone.blockID);
		world.setBlock(i + 1, j + 4, k + 19, Block.cobblestone.blockID);
		world.setBlock(i + 1, j + 4, k + 20, Block.cobblestone.blockID);
		world.setBlock(i + 1, j + 5, k + 1, Block.brick.blockID);
		world.setBlock(i + 1, j + 5, k + 2, Block.brick.blockID);
		world.setBlock(i + 1, j + 5, k + 3, Block.brick.blockID);
		world.setBlock(i + 1, j + 5, k + 4, Block.brick.blockID);
		world.setBlock(i + 1, j + 5, k + 5, Block.brick.blockID);
		world.setBlock(i + 1, j + 5, k + 6, Block.brick.blockID);
		world.setBlock(i + 1, j + 5, k + 7, Block.brick.blockID);
		world.setBlock(i + 1, j + 5, k + 8, Block.brick.blockID);
		world.setBlock(i + 1, j + 5, k + 9, Block.fenceIron.blockID);
		world.setBlock(i + 1, j + 5, k + 10, Block.brick.blockID);
		world.setBlock(i + 1, j + 5, k + 11, Block.brick.blockID);
		world.setBlock(i + 1, j + 5, k + 12, Block.brick.blockID);
		world.setBlock(i + 1, j + 5, k + 13, Block.brick.blockID);
		world.setBlock(i + 1, j + 5, k + 14, Block.brick.blockID);
		world.setBlock(i + 1, j + 5, k + 15, Block.brick.blockID);
		world.setBlock(i + 1, j + 5, k + 16, Block.brick.blockID);
		world.setBlock(i + 1, j + 5, k + 17, Block.brick.blockID);
		world.setBlock(i + 1, j + 5, k + 18, Block.cobblestone.blockID);
		world.setBlock(i + 1, j + 5, k + 19, Block.cobblestone.blockID);
		world.setBlock(i + 1, j + 5, k + 20, Block.cobblestone.blockID);
		world.setBlock(i + 1, j + 6, k + 1, Block.brick.blockID);
		world.setBlock(i + 1, j + 6, k + 2, Block.brick.blockID);
		world.setBlock(i + 1, j + 6, k + 3, Block.brick.blockID);
		world.setBlock(i + 1, j + 6, k + 4, Block.brick.blockID);
		world.setBlock(i + 1, j + 6, k + 5, Block.brick.blockID);
		world.setBlock(i + 1, j + 6, k + 6, Block.brick.blockID);
		world.setBlock(i + 1, j + 6, k + 7, Block.brick.blockID);
		world.setBlock(i + 1, j + 6, k + 8, Block.brick.blockID);
		world.setBlock(i + 1, j + 6, k + 9, Block.brick.blockID);
		world.setBlock(i + 1, j + 6, k + 10, Block.brick.blockID);
		world.setBlock(i + 1, j + 6, k + 11, Block.brick.blockID);
		world.setBlock(i + 1, j + 6, k + 12, Block.brick.blockID);
		world.setBlock(i + 1, j + 6, k + 13, Block.brick.blockID);
		world.setBlock(i + 1, j + 6, k + 14, Block.brick.blockID);
		world.setBlock(i + 1, j + 6, k + 15, Block.brick.blockID);
		world.setBlock(i + 1, j + 6, k + 16, Block.brick.blockID);
		world.setBlock(i + 1, j + 6, k + 17, Block.brick.blockID);
		world.setBlock(i + 1, j + 6, k + 18, Block.cobblestone.blockID);
		world.setBlock(i + 1, j + 6, k + 19, Block.cobblestone.blockID);
		world.setBlock(i + 1, j + 6, k + 20, Block.cobblestone.blockID);
		world.setBlock(i + 1, j + 7, k + 1, Block.brick.blockID);
		world.setBlock(i + 1, j + 7, k + 2, Block.brick.blockID);
		world.setBlock(i + 1, j + 7, k + 3, Block.brick.blockID);
		world.setBlock(i + 1, j + 7, k + 4, Block.brick.blockID);
		world.setBlock(i + 1, j + 7, k + 5, Block.brick.blockID);
		world.setBlock(i + 1, j + 7, k + 6, Block.brick.blockID);
		world.setBlock(i + 1, j + 7, k + 7, Block.brick.blockID);
		world.setBlock(i + 1, j + 7, k + 8, Block.brick.blockID);
		world.setBlock(i + 1, j + 7, k + 9, Block.brick.blockID);
		world.setBlock(i + 1, j + 7, k + 10, Block.brick.blockID);
		world.setBlock(i + 1, j + 7, k + 11, Block.brick.blockID);
		world.setBlock(i + 1, j + 7, k + 12, Block.brick.blockID);
		world.setBlock(i + 1, j + 7, k + 13, Block.brick.blockID);
		world.setBlock(i + 1, j + 7, k + 14, Block.brick.blockID);
		world.setBlock(i + 1, j + 7, k + 15, Block.brick.blockID);
		world.setBlock(i + 1, j + 7, k + 16, Block.brick.blockID);
		world.setBlock(i + 1, j + 7, k + 17, Block.brick.blockID);
		world.setBlock(i + 1, j + 7, k + 18, Block.cobblestone.blockID);
		world.setBlock(i + 1, j + 7, k + 19, Block.cobblestone.blockID);
		world.setBlock(i + 1, j + 7, k + 20, Block.cobblestone.blockID);
		world.setBlock(i + 1, j + 8, k + 1, Block.brick.blockID);
		world.setBlock(i + 1, j + 8, k + 2, Block.brick.blockID);
		world.setBlock(i + 1, j + 8, k + 3, Block.brick.blockID);
		world.setBlock(i + 1, j + 8, k + 4, Block.brick.blockID);
		world.setBlock(i + 1, j + 8, k + 5, Block.brick.blockID);
		world.setBlock(i + 1, j + 8, k + 6, Block.brick.blockID);
		world.setBlock(i + 1, j + 8, k + 7, Block.brick.blockID);
		world.setBlock(i + 1, j + 8, k + 8, Block.brick.blockID);
		world.setBlock(i + 1, j + 8, k + 9, Block.brick.blockID);
		world.setBlock(i + 1, j + 8, k + 10, Block.brick.blockID);
		world.setBlock(i + 1, j + 8, k + 11, Block.brick.blockID);
		world.setBlock(i + 1, j + 8, k + 12, Block.brick.blockID);
		world.setBlock(i + 1, j + 8, k + 13, Block.brick.blockID);
		world.setBlock(i + 1, j + 8, k + 14, Block.brick.blockID);
		world.setBlock(i + 1, j + 8, k + 15, Block.brick.blockID);
		world.setBlock(i + 1, j + 8, k + 16, Block.brick.blockID);
		world.setBlock(i + 1, j + 8, k + 17, Block.brick.blockID);
		world.setBlock(i + 1, j + 9, k + 1, Block.brick.blockID);
		world.setBlock(i + 1, j + 9, k + 2, Block.brick.blockID);
		world.setBlock(i + 1, j + 9, k + 3, Block.brick.blockID);
		world.setBlock(i + 1, j + 9, k + 4, Block.brick.blockID);
		world.setBlock(i + 1, j + 9, k + 5, Block.brick.blockID);
		world.setBlock(i + 1, j + 9, k + 6, Block.brick.blockID);
		world.setBlock(i + 1, j + 9, k + 7, Block.brick.blockID);
		world.setBlock(i + 1, j + 9, k + 8, Block.brick.blockID);
		world.setBlock(i + 1, j + 9, k + 9, Block.brick.blockID);
		world.setBlock(i + 1, j + 9, k + 10, Block.brick.blockID);
		world.setBlock(i + 1, j + 9, k + 11, Block.brick.blockID);
		world.setBlock(i + 1, j + 9, k + 12, Block.brick.blockID);
		world.setBlock(i + 1, j + 9, k + 13, Block.brick.blockID);
		world.setBlock(i + 1, j + 9, k + 14, Block.brick.blockID);
		world.setBlock(i + 1, j + 9, k + 15, Block.brick.blockID);
		world.setBlock(i + 1, j + 9, k + 16, Block.brick.blockID);
		world.setBlock(i + 1, j + 9, k + 17, Block.brick.blockID);
		world.setBlock(i + 1, j + 10, k + 1, Block.brick.blockID);
		world.setBlock(i + 1, j + 10, k + 3, Block.brick.blockID);
		world.setBlock(i + 1, j + 10, k + 4, Block.thinGlass.blockID);
		world.setBlock(i + 1, j + 10, k + 5, Block.thinGlass.blockID);
		world.setBlock(i + 1, j + 10, k + 6, Block.brick.blockID);
		world.setBlock(i + 1, j + 10, k + 7, Block.thinGlass.blockID);
		world.setBlock(i + 1, j + 10, k + 8, Block.thinGlass.blockID);
		world.setBlock(i + 1, j + 10, k + 9, Block.brick.blockID);
		world.setBlock(i + 1, j + 10, k + 10, Block.thinGlass.blockID);
		world.setBlock(i + 1, j + 10, k + 11, Block.thinGlass.blockID);
		world.setBlock(i + 1, j + 10, k + 12, Block.brick.blockID);
		world.setBlock(i + 1, j + 10, k + 13, Block.brick.blockID);
		world.setBlock(i + 1, j + 10, k + 14, Block.brick.blockID);
		world.setBlock(i + 1, j + 10, k + 15, Block.stoneSingleSlab.blockID);
		world.setBlock(i + 1, j + 10, k + 16, Block.stoneSingleSlab.blockID);
		world.setBlock(i + 1, j + 10, k + 17, Block.stoneSingleSlab.blockID);
		world.setBlock(i + 1, j + 11, k + 1, Block.brick.blockID);
		world.setBlock(i + 1, j + 11, k + 2, Block.thinGlass.blockID);
		world.setBlock(i + 1, j + 11, k + 3, Block.brick.blockID);
		world.setBlock(i + 1, j + 11, k + 4, Block.thinGlass.blockID);
		world.setBlock(i + 1, j + 11, k + 5, Block.thinGlass.blockID);
		world.setBlock(i + 1, j + 11, k + 6, Block.brick.blockID);
		world.setBlock(i + 1, j + 11, k + 7, Block.thinGlass.blockID);
		world.setBlock(i + 1, j + 11, k + 9, Block.brick.blockID);
		world.setBlock(i + 1, j + 11, k + 10, Block.brick.blockID);
		world.setBlock(i + 1, j + 11, k + 11, Block.brick.blockID);
		world.setBlock(i + 1, j + 11, k + 12, Block.brick.blockID);
		world.setBlock(i + 1, j + 11, k + 13, Block.brick.blockID);
		world.setBlock(i + 1, j + 11, k + 14, Block.brick.blockID);
		world.setBlock(i + 1, j + 12, k + 1, Block.brick.blockID);
		world.setBlock(i + 1, j + 12, k + 2, Block.brick.blockID);
		world.setBlock(i + 1, j + 12, k + 3, Block.brick.blockID);
		world.setBlock(i + 1, j + 12, k + 4, Block.thinGlass.blockID);
		world.setBlock(i + 1, j + 12, k + 5, Block.thinGlass.blockID);
		world.setBlock(i + 1, j + 12, k + 6, Block.brick.blockID);
		world.setBlock(i + 1, j + 12, k + 7, Block.brick.blockID);
		world.setBlock(i + 1, j + 12, k + 8, Block.brick.blockID);
		world.setBlock(i + 1, j + 12, k + 9, Block.brick.blockID);
		world.setBlock(i + 1, j + 12, k + 10, Block.brick.blockID);
		world.setBlock(i + 1, j + 12, k + 11, Block.brick.blockID);
		world.setBlock(i + 1, j + 13, k + 1, Block.brick.blockID);
		world.setBlock(i + 1, j + 13, k + 2, Block.brick.blockID);
		world.setBlock(i + 1, j + 13, k + 3, Block.brick.blockID);
		world.setBlock(i + 1, j + 13, k + 4, Block.brick.blockID);
		world.setBlock(i + 1, j + 13, k + 5, Block.brick.blockID);
		world.setBlock(i + 1, j + 13, k + 6, Block.brick.blockID);
		world.setBlock(i + 1, j + 13, k + 7, Block.brick.blockID);
		world.setBlock(i + 1, j + 13, k + 8, Block.brick.blockID);
		world.setBlock(i + 1, j + 14, k + 3, Block.brick.blockID);
		world.setBlock(i + 1, j + 14, k + 4, Block.brick.blockID);
		world.setBlock(i + 1, j + 14, k + 5, Block.brick.blockID);
		world.setBlock(i + 1, j + 14, k + 6, Block.brick.blockID);
		world.setBlock(i + 1, j + 14, k + 7, Block.brick.blockID);
		world.setBlock(i + 1, j + 14, k + 8, Block.brick.blockID);
		world.setBlock(i + 1, j + 15, k + 6, Block.brick.blockID);
		world.setBlock(i + 1, j + 15, k + 7, Block.brick.blockID);
		world.setBlock(i + 1, j + 15, k + 8, Block.brick.blockID);
		world.setBlock(i + 2, j + 0, k + 0, Block.grass.blockID);
		world.setBlock(i + 2, j + 0, k + 1, Block.dirt.blockID);
		world.setBlockAndMetadata(i + 2, j + 0, k + 2, Block.planks.blockID, 3);
		world.setBlockAndMetadata(i + 2, j + 0, k + 3, Block.planks.blockID, 3);
		world.setBlockAndMetadata(i + 2, j + 0, k + 4, Block.planks.blockID, 3);
		world.setBlockAndMetadata(i + 2, j + 0, k + 6, Block.planks.blockID, 3);
		world.setBlockAndMetadata(i + 2, j + 0, k + 7, Block.planks.blockID, 3);
		world.setBlockAndMetadata(i + 2, j + 0, k + 8, Block.planks.blockID, 3);
		world.setBlockAndMetadata(i + 2, j + 0, k + 9, Block.planks.blockID, 3);
		world.setBlockAndMetadata(i + 2, j + 0, k + 10, Block.planks.blockID, 3);
		world.setBlockAndMetadata(i + 2, j + 0, k + 11, Block.planks.blockID, 3);
		world.setBlockAndMetadata(i + 2, j + 0, k + 12, Block.planks.blockID, 3);
		world.setBlockAndMetadata(i + 2, j + 0, k + 13, Block.planks.blockID, 3);
		world.setBlockAndMetadata(i + 2, j + 0, k + 14, Block.planks.blockID, 3);
		world.setBlockAndMetadata(i + 2, j + 0, k + 15, Block.planks.blockID, 3);
		world.setBlockAndMetadata(i + 2, j + 0, k + 16, Block.planks.blockID, 3);
		world.setBlock(i + 2, j + 0, k + 17, Block.dirt.blockID);
		world.setBlock(i + 2, j + 0, k + 18, Block.dirt.blockID);
		world.setBlock(i + 2, j + 0, k + 19, Block.netherrack.blockID);
		world.setBlock(i + 2, j + 0, k + 20, Block.dirt.blockID);
		world.setBlock(i + 2, j + 0, k + 21, Block.dirt.blockID);
		world.setBlock(i + 2, j + 0, k + 22, Block.grass.blockID);
		world.setBlock(i + 2, j + 0, k + 23, Block.grass.blockID);
		world.setBlock(i + 2, j + 0, k + 24, Block.grass.blockID);
		world.setBlock(i + 2, j + 1, k + 1, Block.stoneBrick.blockID);
		world.setBlock(i + 2, j + 1, k + 17, Block.stoneBrick.blockID);
		world.setBlock(i + 2, j + 1, k + 18, Block.cobblestone.blockID);
		world.setBlockAndMetadata(i + 2, j + 1, k + 19, Block.fire.blockID, 15);
		world.setBlock(i + 2, j + 1, k + 20, Block.cobblestone.blockID);
		world.setBlock(i + 2, j + 1, k + 21, Block.cobblestone.blockID);
		world.setBlock(i + 2, j + 2, k + 1, Block.brick.blockID);
		world.setBlock(i + 2, j + 2, k + 17, Block.brick.blockID);
		world.setBlock(i + 2, j + 2, k + 18, Block.cobblestone.blockID);
		world.setBlock(i + 2, j + 2, k + 20, Block.cobblestone.blockID);
		world.setBlock(i + 2, j + 2, k + 21, Block.cobblestone.blockID);
		world.setBlock(i + 2, j + 3, k + 1, Block.brick.blockID);
		world.setBlock(i + 2, j + 3, k + 2, Block.dirt.blockID);
		world.setBlock(i + 2, j + 3, k + 17, Block.brick.blockID);
		world.setBlock(i + 2, j + 3, k + 18, Block.cobblestone.blockID);
		world.setBlock(i + 2, j + 3, k + 20, Block.cobblestone.blockID);
		world.setBlock(i + 2, j + 3, k + 21, Block.cobblestone.blockID);
		world.setBlock(i + 2, j + 4, k + 1, Block.brick.blockID);
		world.setBlock(i + 2, j + 4, k + 17, Block.brick.blockID);
		world.setBlock(i + 2, j + 4, k + 18, Block.cobblestone.blockID);
		world.setBlock(i + 2, j + 4, k + 20, Block.cobblestone.blockID);
		world.setBlock(i + 2, j + 4, k + 21, Block.cobblestone.blockID);
		world.setBlock(i + 2, j + 5, k + 1, Block.brick.blockID);
		world.setBlock(i + 2, j + 5, k + 17, Block.brick.blockID);
		world.setBlock(i + 2, j + 5, k + 18, Block.cobblestone.blockID);
		world.setBlock(i + 2, j + 5, k + 20, Block.cobblestone.blockID);
		world.setBlock(i + 2, j + 5, k + 21, Block.cobblestone.blockID);
		world.setBlock(i + 2, j + 6, k + 1, Block.brick.blockID);
		world.setBlock(i + 2, j + 6, k + 17, Block.brick.blockID);
		world.setBlock(i + 2, j + 6, k + 18, Block.cobblestone.blockID);
		world.setBlock(i + 2, j + 6, k + 20, Block.cobblestone.blockID);
		world.setBlock(i + 2, j + 6, k + 21, Block.cobblestone.blockID);
		world.setBlock(i + 2, j + 7, k + 1, Block.brick.blockID);
		world.setBlock(i + 2, j + 7, k + 17, Block.brick.blockID);
		world.setBlock(i + 2, j + 7, k + 18, Block.cobblestone.blockID);
		world.setBlock(i + 2, j + 7, k + 20, Block.cobblestone.blockID);
		world.setBlock(i + 2, j + 7, k + 21, Block.cobblestone.blockID);
		world.setBlock(i + 2, j + 8, k + 1, Block.brick.blockID);
		world.setBlock(i + 2, j + 8, k + 17, Block.brick.blockID);
		world.setBlock(i + 2, j + 8, k + 19, Block.cobblestone.blockID);
		world.setBlock(i + 2, j + 9, k + 1, Block.brick.blockID);
		world.setBlock(i + 2, j + 9, k + 15, Block.brick.blockID);
		world.setBlock(i + 2, j + 9, k + 16, Block.brick.blockID);
		world.setBlock(i + 2, j + 9, k + 17, Block.brick.blockID);
		world.setBlock(i + 2, j + 9, k + 19, Block.cobblestone.blockID);
		world.setBlock(i + 2, j + 10, k + 1, Block.brick.blockID);
		world.setBlock(i + 2, j + 10, k + 12, Block.brick.blockID);
		world.setBlock(i + 2, j + 10, k + 13, Block.brick.blockID);
		world.setBlock(i + 2, j + 10, k + 14, Block.brick.blockID);
		world.setBlock(i + 2, j + 10, k + 15, Block.stoneSingleSlab.blockID);
		world.setBlock(i + 2, j + 10, k + 16, Block.stoneSingleSlab.blockID);
		world.setBlock(i + 2, j + 10, k + 17, Block.stoneSingleSlab.blockID);
		world.setBlock(i + 2, j + 10, k + 19, Block.cobblestone.blockID);
		world.setBlock(i + 2, j + 11, k + 1, Block.brick.blockID);
		world.setBlock(i + 2, j + 11, k + 9, Block.brick.blockID);
		world.setBlock(i + 2, j + 11, k + 10, Block.brick.blockID);
		world.setBlock(i + 2, j + 11, k + 11, Block.brick.blockID);
		world.setBlock(i + 2, j + 11, k + 12, Block.stoneSingleSlab.blockID);
		world.setBlock(i + 2, j + 11, k + 13, Block.stoneSingleSlab.blockID);
		world.setBlock(i + 2, j + 11, k + 14, Block.stoneSingleSlab.blockID);
		world.setBlock(i + 2, j + 11, k + 19, Block.cobblestone.blockID);
		world.setBlock(i + 2, j + 12, k + 1, Block.brick.blockID);
		world.setBlock(i + 2, j + 12, k + 2, Block.brick.blockID);
		world.setBlock(i + 2, j + 12, k + 6, Block.brick.blockID);
		world.setBlock(i + 2, j + 12, k + 8, Block.brick.blockID);
		world.setBlock(i + 2, j + 12, k + 9, Block.stoneSingleSlab.blockID);
		world.setBlock(i + 2, j + 12, k + 10, Block.stoneSingleSlab.blockID);
		world.setBlock(i + 2, j + 12, k + 11, Block.stoneSingleSlab.blockID);
		world.setBlock(i + 2, j + 12, k + 19, Block.cobblestone.blockID);
		world.setBlock(i + 2, j + 13, k + 1, Block.stoneSingleSlab.blockID);
		world.setBlock(i + 2, j + 13, k + 2, Block.stoneSingleSlab.blockID);
		world.setBlock(i + 2, j + 13, k + 3, Block.brick.blockID);
		world.setBlock(i + 2, j + 13, k + 4, Block.brick.blockID);
		world.setBlock(i + 2, j + 13, k + 5, Block.brick.blockID);
		world.setBlock(i + 2, j + 13, k + 6, Block.brick.blockID);
		world.setBlock(i + 2, j + 13, k + 8, Block.brick.blockID);
		world.setBlock(i + 2, j + 13, k + 19, Block.cobblestone.blockID);
		world.setBlock(i + 2, j + 14, k + 3, Block.stoneSingleSlab.blockID);
		world.setBlock(i + 2, j + 14, k + 4, Block.stoneSingleSlab.blockID);
		world.setBlock(i + 2, j + 14, k + 5, Block.stoneSingleSlab.blockID);
		world.setBlock(i + 2, j + 14, k + 6, Block.brick.blockID);
		world.setBlock(i + 2, j + 14, k + 8, Block.brick.blockID);
		world.setBlock(i + 2, j + 14, k + 19, Block.cobblestone.blockID);
		world.setBlock(i + 2, j + 15, k + 6, Block.brick.blockID);
		world.setBlock(i + 2, j + 15, k + 7, Block.brick.blockID);
		world.setBlock(i + 2, j + 15, k + 8, Block.brick.blockID);
		world.setBlock(i + 3, j + 0, k + 0, Block.grass.blockID);
		world.setBlock(i + 3, j + 0, k + 1, Block.dirt.blockID);
		world.setBlockAndMetadata(i + 3, j + 0, k + 2, Block.planks.blockID, 3);
		world.setBlockAndMetadata(i + 3, j + 0, k + 3, Block.planks.blockID, 3);
		world.setBlockAndMetadata(i + 3, j + 0, k + 6, Block.planks.blockID, 3);
		world.setBlockAndMetadata(i + 3, j + 0, k + 7, Block.planks.blockID, 3);
		world.setBlockAndMetadata(i + 3, j + 0, k + 8, Block.planks.blockID, 3);
		world.setBlockAndMetadata(i + 3, j + 0, k + 9, Block.planks.blockID, 3);
		world.setBlockAndMetadata(i + 3, j + 0, k + 10, Block.planks.blockID, 3);
		world.setBlockAndMetadata(i + 3, j + 0, k + 11, Block.planks.blockID, 3);
		world.setBlockAndMetadata(i + 3, j + 0, k + 12, Block.planks.blockID, 3);
		world.setBlockAndMetadata(i + 3, j + 0, k + 13, Block.planks.blockID, 3);
		world.setBlockAndMetadata(i + 3, j + 0, k + 14, Block.planks.blockID, 3);
		world.setBlockAndMetadata(i + 3, j + 0, k + 15, Block.planks.blockID, 3);
		world.setBlockAndMetadata(i + 3, j + 0, k + 16, Block.planks.blockID, 3);
		world.setBlock(i + 3, j + 0, k + 17, Block.dirt.blockID);
		world.setBlock(i + 3, j + 0, k + 18, Block.netherrack.blockID);
		world.setBlock(i + 3, j + 0, k + 19, Block.netherrack.blockID);
		world.setBlock(i + 3, j + 0, k + 20, Block.netherrack.blockID);
		world.setBlock(i + 3, j + 0, k + 21, Block.dirt.blockID);
		world.setBlock(i + 3, j + 0, k + 22, Block.dirt.blockID);
		world.setBlock(i + 3, j + 0, k + 23, Block.grass.blockID);
		world.setBlock(i + 3, j + 0, k + 24, Block.grass.blockID);
		world.setBlock(i + 3, j + 1, k + 1, Block.stoneBrick.blockID);
		world.setBlock(i + 3, j + 1, k + 16, Block.cobblestone.blockID);
		world.setBlock(i + 3, j + 1, k + 17, Block.brick.blockID);
		world.setBlockAndMetadata(i + 3, j + 1, k + 18, Block.fire.blockID, 15);
		world.setBlockAndMetadata(i + 3, j + 1, k + 19, Block.fire.blockID, 15);
		world.setBlockAndMetadata(i + 3, j + 1, k + 20, Block.fire.blockID, 15);
		world.setBlock(i + 3, j + 1, k + 21, Block.cobblestone.blockID);
		world.setBlock(i + 3, j + 1, k + 22, Block.cobblestone.blockID);
		world.setBlock(i + 3, j + 2, k + 1, Block.brick.blockID);
		world.setBlock(i + 3, j + 2, k + 2, Block.dirt.blockID);
		world.setBlock(i + 3, j + 2, k + 16, Block.cobblestone.blockID);
		world.setBlock(i + 3, j + 2, k + 17, Block.brick.blockID);
		world.setBlock(i + 3, j + 2, k + 21, Block.cobblestone.blockID);
		world.setBlock(i + 3, j + 2, k + 22, Block.cobblestone.blockID);
		world.setBlock(i + 3, j + 3, k + 1, Block.fenceIron.blockID);
		world.setBlock(i + 3, j + 3, k + 16, Block.cobblestone.blockID);
		world.setBlock(i + 3, j + 3, k + 17, Block.brick.blockID);
		world.setBlock(i + 3, j + 3, k + 21, Block.cobblestone.blockID);
		world.setBlock(i + 3, j + 3, k + 22, Block.cobblestone.blockID);
		world.setBlock(i + 3, j + 4, k + 1, Block.thinGlass.blockID);
		world.setBlock(i + 3, j + 4, k + 16, Block.cobblestone.blockID);
		world.setBlock(i + 3, j + 4, k + 17, Block.brick.blockID);
		world.setBlock(i + 3, j + 4, k + 21, Block.cobblestone.blockID);
		world.setBlock(i + 3, j + 4, k + 22, Block.cobblestone.blockID);
		world.setBlock(i + 3, j + 5, k + 16, Block.cobblestone.blockID);
		world.setBlock(i + 3, j + 5, k + 17, Block.brick.blockID);
		world.setBlock(i + 3, j + 5, k + 21, Block.cobblestone.blockID);
		world.setBlock(i + 3, j + 5, k + 22, Block.cobblestone.blockID);
		world.setBlock(i + 3, j + 6, k + 1, Block.thinGlass.blockID);
		world.setBlock(i + 3, j + 6, k + 16, Block.cobblestone.blockID);
		world.setBlock(i + 3, j + 6, k + 17, Block.brick.blockID);
		world.setBlock(i + 3, j + 6, k + 21, Block.cobblestone.blockID);
		world.setBlock(i + 3, j + 6, k + 22, Block.cobblestone.blockID);
		world.setBlock(i + 3, j + 7, k + 1, Block.thinGlass.blockID);
		world.setBlock(i + 3, j + 7, k + 16, Block.cobblestone.blockID);
		world.setBlock(i + 3, j + 7, k + 17, Block.brick.blockID);
		world.setBlock(i + 3, j + 7, k + 21, Block.cobblestone.blockID);
		world.setBlock(i + 3, j + 7, k + 22, Block.cobblestone.blockID);
		world.setBlock(i + 3, j + 8, k + 1, Block.thinGlass.blockID);
		world.setBlock(i + 3, j + 8, k + 17, Block.brick.blockID);
		world.setBlock(i + 3, j + 8, k + 18, Block.cobblestone.blockID);
		world.setBlock(i + 3, j + 8, k + 20, Block.cobblestone.blockID);
		world.setBlock(i + 3, j + 9, k + 1, Block.brick.blockID);
		world.setBlock(i + 3, j + 9, k + 15, Block.brick.blockID);
		world.setBlock(i + 3, j + 9, k + 16, Block.brick.blockID);
		world.setBlock(i + 3, j + 9, k + 17, Block.brick.blockID);
		world.setBlock(i + 3, j + 9, k + 18, Block.cobblestone.blockID);
		world.setBlock(i + 3, j + 9, k + 20, Block.cobblestone.blockID);
		world.setBlock(i + 3, j + 10, k + 1, Block.brick.blockID);
		world.setBlock(i + 3, j + 10, k + 12, Block.brick.blockID);
		world.setBlock(i + 3, j + 10, k + 13, Block.brick.blockID);
		world.setBlock(i + 3, j + 10, k + 14, Block.brick.blockID);
		world.setBlock(i + 3, j + 10, k + 15, Block.stoneSingleSlab.blockID);
		world.setBlock(i + 3, j + 10, k + 16, Block.stoneSingleSlab.blockID);
		world.setBlock(i + 3, j + 10, k + 17, Block.stoneSingleSlab.blockID);
		world.setBlock(i + 3, j + 10, k + 18, Block.cobblestone.blockID);
		world.setBlock(i + 3, j + 10, k + 20, Block.cobblestone.blockID);
		world.setBlock(i + 3, j + 11, k + 1, Block.brick.blockID);
		world.setBlock(i + 3, j + 11, k + 9, Block.brick.blockID);
		world.setBlock(i + 3, j + 11, k + 10, Block.brick.blockID);
		world.setBlock(i + 3, j + 11, k + 11, Block.brick.blockID);
		world.setBlock(i + 3, j + 11, k + 12, Block.stoneSingleSlab.blockID);
		world.setBlock(i + 3, j + 11, k + 13, Block.stoneSingleSlab.blockID);
		world.setBlock(i + 3, j + 11, k + 14, Block.stoneSingleSlab.blockID);
		world.setBlock(i + 3, j + 11, k + 18, Block.cobblestone.blockID);
		world.setBlock(i + 3, j + 11, k + 20, Block.cobblestone.blockID);
		world.setBlock(i + 3, j + 12, k + 1, Block.brick.blockID);
		world.setBlock(i + 3, j + 12, k + 2, Block.brick.blockID);
		world.setBlock(i + 3, j + 12, k + 6, Block.brick.blockID);
		world.setBlock(i + 3, j + 12, k + 8, Block.brick.blockID);
		world.setBlock(i + 3, j + 12, k + 9, Block.stoneSingleSlab.blockID);
		world.setBlock(i + 3, j + 12, k + 10, Block.stoneSingleSlab.blockID);
		world.setBlock(i + 3, j + 12, k + 11, Block.stoneSingleSlab.blockID);
		world.setBlock(i + 3, j + 12, k + 18, Block.cobblestone.blockID);
		world.setBlock(i + 3, j + 12, k + 20, Block.cobblestone.blockID);
		world.setBlock(i + 3, j + 13, k + 1, Block.stoneSingleSlab.blockID);
		world.setBlock(i + 3, j + 13, k + 2, Block.stoneSingleSlab.blockID);
		world.setBlock(i + 3, j + 13, k + 3, Block.brick.blockID);
		world.setBlock(i + 3, j + 13, k + 4, Block.brick.blockID);
		world.setBlock(i + 3, j + 13, k + 5, Block.brick.blockID);
		world.setBlock(i + 3, j + 13, k + 6, Block.brick.blockID);
		world.setBlock(i + 3, j + 13, k + 8, Block.glass.blockID);
		world.setBlock(i + 3, j + 13, k + 18, Block.cobblestone.blockID);
		world.setBlock(i + 3, j + 13, k + 20, Block.cobblestone.blockID);
		world.setBlock(i + 3, j + 14, k + 3, Block.stoneSingleSlab.blockID);
		world.setBlock(i + 3, j + 14, k + 4, Block.stoneSingleSlab.blockID);
		world.setBlock(i + 3, j + 14, k + 5, Block.stoneSingleSlab.blockID);
		world.setBlock(i + 3, j + 14, k + 6, Block.brick.blockID);
		world.setBlock(i + 3, j + 14, k + 8, Block.glass.blockID);
		world.setBlock(i + 3, j + 14, k + 18, Block.cobblestone.blockID);
		world.setBlock(i + 3, j + 14, k + 20, Block.cobblestone.blockID);
		world.setBlock(i + 3, j + 15, k + 6, Block.brick.blockID);
		world.setBlock(i + 3, j + 15, k + 7, Block.brick.blockID);
		world.setBlock(i + 3, j + 15, k + 8, Block.brick.blockID);
		world.setBlock(i + 3, j + 15, k + 19, Block.cobblestone.blockID);
		world.setBlock(i + 3, j + 16, k + 19, Block.cobblestone.blockID);
		world.setBlock(i + 3, j + 17, k + 19, Block.cobblestone.blockID);
		world.setBlock(i + 3, j + 18, k + 19, Block.cobblestone.blockID);
		world.setBlock(i + 3, j + 19, k + 19, Block.cobblestone.blockID);
		world.setBlock(i + 4, j + 0, k + 0, Block.grass.blockID);
		world.setBlock(i + 4, j + 0, k + 1, Block.dirt.blockID);
		world.setBlockAndMetadata(i + 4, j + 0, k + 2, Block.planks.blockID, 3);
		world.setBlockAndMetadata(i + 4, j + 0, k + 5, Block.planks.blockID, 3);
		world.setBlockAndMetadata(i + 4, j + 0, k + 6, Block.planks.blockID, 3);
		world.setBlockAndMetadata(i + 4, j + 0, k + 7, Block.planks.blockID, 3);
		world.setBlockAndMetadata(i + 4, j + 0, k + 8, Block.planks.blockID, 3);
		world.setBlockAndMetadata(i + 4, j + 0, k + 9, Block.planks.blockID, 3);
		world.setBlockAndMetadata(i + 4, j + 0, k + 10, Block.planks.blockID, 3);
		world.setBlockAndMetadata(i + 4, j + 0, k + 11, Block.planks.blockID, 3);
		world.setBlockAndMetadata(i + 4, j + 0, k + 12, Block.planks.blockID, 3);
		world.setBlockAndMetadata(i + 4, j + 0, k + 13, Block.planks.blockID, 3);
		world.setBlockAndMetadata(i + 4, j + 0, k + 14, Block.planks.blockID, 3);
		world.setBlockAndMetadata(i + 4, j + 0, k + 15, Block.planks.blockID, 3);
		world.setBlockAndMetadata(i + 4, j + 0, k + 16, Block.planks.blockID, 3);
		world.setBlock(i + 4, j + 0, k + 17, Block.dirt.blockID);
		world.setBlock(i + 4, j + 0, k + 18, Block.netherrack.blockID);
		world.setBlock(i + 4, j + 0, k + 19, Block.netherrack.blockID);
		world.setBlock(i + 4, j + 0, k + 20, Block.netherrack.blockID);
		world.setBlock(i + 4, j + 0, k + 21, Block.netherrack.blockID);
		world.setBlock(i + 4, j + 0, k + 22, Block.dirt.blockID);
		world.setBlock(i + 4, j + 0, k + 23, Block.dirt.blockID);
		world.setBlock(i + 4, j + 0, k + 24, Block.grass.blockID);
		world.setBlock(i + 4, j + 1, k + 1, Block.stoneBrick.blockID);
		world.setBlock(i + 4, j + 1, k + 15, Block.cobblestone.blockID);
		world.setBlock(i + 4, j + 1, k + 16, Block.cobblestone.blockID);
		world.setBlock(i + 4, j + 1, k + 17, Block.brick.blockID);
		world.setBlockAndMetadata(i + 4, j + 1, k + 18, Block.fire.blockID, 15);
		world.setBlockAndMetadata(i + 4, j + 1, k + 19, Block.fire.blockID, 15);
		world.setBlockAndMetadata(i + 4, j + 1, k + 20, Block.fire.blockID, 15);
		world.setBlockAndMetadata(i + 4, j + 1, k + 21, Block.fire.blockID, 15);
		world.setBlock(i + 4, j + 1, k + 22, Block.cobblestone.blockID);
		world.setBlock(i + 4, j + 1, k + 23, Block.cobblestone.blockID);
		world.setBlock(i + 4, j + 2, k + 1, Block.brick.blockID);
		world.setBlock(i + 4, j + 2, k + 15, Block.cobblestone.blockID);
		world.setBlock(i + 4, j + 2, k + 16, Block.cobblestone.blockID);
		world.setBlock(i + 4, j + 2, k + 17, Block.brick.blockID);
		world.setBlock(i + 4, j + 2, k + 22, Block.cobblestone.blockID);
		world.setBlock(i + 4, j + 2, k + 23, Block.cobblestone.blockID);
		world.setBlock(i + 4, j + 3, k + 1, Block.thinGlass.blockID);
		world.setBlock(i + 4, j + 3, k + 15, Block.cobblestone.blockID);
		world.setBlock(i + 4, j + 3, k + 16, Block.cobblestone.blockID);
		world.setBlock(i + 4, j + 3, k + 17, Block.brick.blockID);
		world.setBlock(i + 4, j + 3, k + 22, Block.cobblestone.blockID);
		world.setBlock(i + 4, j + 3, k + 23, Block.cobblestone.blockID);
		world.setBlock(i + 4, j + 4, k + 1, Block.thinGlass.blockID);
		world.setBlock(i + 4, j + 4, k + 15, Block.cobblestone.blockID);
		world.setBlock(i + 4, j + 4, k + 16, Block.cobblestone.blockID);
		world.setBlock(i + 4, j + 4, k + 17, Block.brick.blockID);
		world.setBlock(i + 4, j + 4, k + 22, Block.cobblestone.blockID);
		world.setBlock(i + 4, j + 4, k + 23, Block.cobblestone.blockID);
		world.setBlock(i + 4, j + 5, k + 1, Block.thinGlass.blockID);
		world.setBlock(i + 4, j + 5, k + 15, Block.cobblestone.blockID);
		world.setBlock(i + 4, j + 5, k + 16, Block.cobblestone.blockID);
		world.setBlock(i + 4, j + 5, k + 17, Block.brick.blockID);
		world.setBlock(i + 4, j + 5, k + 22, Block.cobblestone.blockID);
		world.setBlock(i + 4, j + 5, k + 23, Block.cobblestone.blockID);
		world.setBlock(i + 4, j + 6, k + 1, Block.thinGlass.blockID);
		world.setBlock(i + 4, j + 6, k + 15, Block.cobblestone.blockID);
		world.setBlock(i + 4, j + 6, k + 16, Block.cobblestone.blockID);
		world.setBlock(i + 4, j + 6, k + 17, Block.brick.blockID);
		world.setBlock(i + 4, j + 6, k + 22, Block.cobblestone.blockID);
		world.setBlock(i + 4, j + 6, k + 23, Block.cobblestone.blockID);
		world.setBlock(i + 4, j + 7, k + 1, Block.thinGlass.blockID);
		world.setBlock(i + 4, j + 7, k + 15, Block.cobblestone.blockID);
		world.setBlock(i + 4, j + 7, k + 16, Block.cobblestone.blockID);
		world.setBlock(i + 4, j + 7, k + 17, Block.brick.blockID);
		world.setBlock(i + 4, j + 7, k + 22, Block.cobblestone.blockID);
		world.setBlock(i + 4, j + 7, k + 23, Block.cobblestone.blockID);
		world.setBlock(i + 4, j + 8, k + 1, Block.thinGlass.blockID);
		world.setBlock(i + 4, j + 8, k + 16, Block.cobblestone.blockID);
		world.setBlock(i + 4, j + 8, k + 17, Block.brick.blockID);
		world.setBlock(i + 4, j + 8, k + 21, Block.cobblestone.blockID);
		world.setBlock(i + 4, j + 9, k + 1, Block.thinGlass.blockID);
		world.setBlock(i + 4, j + 9, k + 15, Block.brick.blockID);
		world.setBlock(i + 4, j + 9, k + 16, Block.brick.blockID);
		world.setBlock(i + 4, j + 9, k + 17, Block.brick.blockID);
		world.setBlock(i + 4, j + 9, k + 21, Block.cobblestone.blockID);
		world.setBlock(i + 4, j + 10, k + 1, Block.brick.blockID);
		world.setBlock(i + 4, j + 10, k + 12, Block.brick.blockID);
		world.setBlock(i + 4, j + 10, k + 13, Block.brick.blockID);
		world.setBlock(i + 4, j + 10, k + 14, Block.brick.blockID);
		world.setBlock(i + 4, j + 10, k + 15, Block.stoneSingleSlab.blockID);
		world.setBlock(i + 4, j + 10, k + 16, Block.stoneSingleSlab.blockID);
		world.setBlock(i + 4, j + 10, k + 17, Block.stoneDoubleSlab.blockID);
		world.setBlock(i + 4, j + 10, k + 21, Block.cobblestone.blockID);
		world.setBlock(i + 4, j + 11, k + 1, Block.brick.blockID);
		world.setBlock(i + 4, j + 11, k + 9, Block.brick.blockID);
		world.setBlock(i + 4, j + 11, k + 10, Block.brick.blockID);
		world.setBlock(i + 4, j + 11, k + 11, Block.brick.blockID);
		world.setBlock(i + 4, j + 11, k + 12, Block.stoneSingleSlab.blockID);
		world.setBlock(i + 4, j + 11, k + 13, Block.stoneSingleSlab.blockID);
		world.setBlock(i + 4, j + 11, k + 14, Block.stoneSingleSlab.blockID);
		world.setBlock(i + 4, j + 11, k + 17, Block.cobblestone.blockID);
		world.setBlock(i + 4, j + 11, k + 21, Block.cobblestone.blockID);
		world.setBlock(i + 4, j + 12, k + 1, Block.brick.blockID);
		world.setBlock(i + 4, j + 12, k + 2, Block.brick.blockID);
		world.setBlock(i + 4, j + 12, k + 6, Block.brick.blockID);
		world.setBlock(i + 4, j + 12, k + 8, Block.brick.blockID);
		world.setBlock(i + 4, j + 12, k + 9, Block.stoneSingleSlab.blockID);
		world.setBlock(i + 4, j + 12, k + 10, Block.stoneSingleSlab.blockID);
		world.setBlock(i + 4, j + 12, k + 11, Block.stoneSingleSlab.blockID);
		world.setBlock(i + 4, j + 12, k + 17, Block.cobblestone.blockID);
		world.setBlock(i + 4, j + 12, k + 21, Block.cobblestone.blockID);
		world.setBlock(i + 4, j + 13, k + 1, Block.stoneSingleSlab.blockID);
		world.setBlock(i + 4, j + 13, k + 2, Block.stoneSingleSlab.blockID);
		world.setBlock(i + 4, j + 13, k + 3, Block.brick.blockID);
		world.setBlock(i + 4, j + 13, k + 4, Block.brick.blockID);
		world.setBlock(i + 4, j + 13, k + 5, Block.brick.blockID);
		world.setBlock(i + 4, j + 13, k + 6, Block.brick.blockID);
		world.setBlock(i + 4, j + 13, k + 8, Block.glass.blockID);
		world.setBlock(i + 4, j + 13, k + 17, Block.cobblestone.blockID);
		world.setBlock(i + 4, j + 13, k + 21, Block.cobblestone.blockID);
		world.setBlock(i + 4, j + 14, k + 3, Block.stoneSingleSlab.blockID);
		world.setBlock(i + 4, j + 14, k + 4, Block.stoneSingleSlab.blockID);
		world.setBlock(i + 4, j + 14, k + 5, Block.stoneSingleSlab.blockID);
		world.setBlock(i + 4, j + 14, k + 6, Block.brick.blockID);
		world.setBlock(i + 4, j + 14, k + 8, Block.glass.blockID);
		world.setBlock(i + 4, j + 14, k + 17, Block.cobblestone.blockID);
		world.setBlock(i + 4, j + 14, k + 21, Block.cobblestone.blockID);
		world.setBlock(i + 4, j + 15, k + 6, Block.brick.blockID);
		world.setBlock(i + 4, j + 15, k + 7, Block.brick.blockID);
		world.setBlock(i + 4, j + 15, k + 8, Block.brick.blockID);
		world.setBlock(i + 4, j + 15, k + 18, Block.cobblestone.blockID);
		world.setBlock(i + 4, j + 15, k + 20, Block.cobblestone.blockID);
		world.setBlock(i + 4, j + 16, k + 18, Block.cobblestone.blockID);
		world.setBlock(i + 4, j + 16, k + 20, Block.cobblestone.blockID);
		world.setBlock(i + 4, j + 17, k + 18, Block.cobblestone.blockID);
		world.setBlock(i + 4, j + 17, k + 20, Block.cobblestone.blockID);
		world.setBlock(i + 4, j + 18, k + 18, Block.cobblestone.blockID);
		world.setBlock(i + 4, j + 18, k + 20, Block.cobblestone.blockID);
		world.setBlock(i + 4, j + 19, k + 18, Block.cobblestone.blockID);
		world.setBlock(i + 4, j + 19, k + 20, Block.cobblestone.blockID);
		world.setBlock(i + 4, j + 20, k + 19, Block.cobblestone.blockID);
		world.setBlock(i + 4, j + 21, k + 19, Block.cobblestone.blockID);
		world.setBlock(i + 4, j + 22, k + 19, Block.cobblestone.blockID);
		world.setBlock(i + 4, j + 23, k + 19, Block.cobblestone.blockID);
		world.setBlock(i + 4, j + 24, k + 19, Block.cobblestone.blockID);
		world.setBlock(i + 4, j + 25, k + 19, Block.cobblestone.blockID);
		world.setBlock(i + 5, j + 0, k + 0, Block.grass.blockID);
		world.setBlock(i + 5, j + 0, k + 1, Block.dirt.blockID);
		world.setBlockAndMetadata(i + 5, j + 0, k + 2, Block.planks.blockID, 3);
		world.setBlockAndMetadata(i + 5, j + 0, k + 3, Block.planks.blockID, 3);
		world.setBlockAndMetadata(i + 5, j + 0, k + 4, Block.planks.blockID, 3);
		world.setBlockAndMetadata(i + 5, j + 0, k + 5, Block.planks.blockID, 3);
		world.setBlockAndMetadata(i + 5, j + 0, k + 6, Block.planks.blockID, 3);
		world.setBlockAndMetadata(i + 5, j + 0, k + 7, Block.planks.blockID, 3);
		world.setBlockAndMetadata(i + 5, j + 0, k + 8, Block.planks.blockID, 3);
		world.setBlockAndMetadata(i + 5, j + 0, k + 9, Block.planks.blockID, 3);
		world.setBlockAndMetadata(i + 5, j + 0, k + 10, Block.planks.blockID, 3);
		world.setBlockAndMetadata(i + 5, j + 0, k + 11, Block.planks.blockID, 3);
		world.setBlockAndMetadata(i + 5, j + 0, k + 12, Block.planks.blockID, 3);
		world.setBlockAndMetadata(i + 5, j + 0, k + 13, Block.planks.blockID, 3);
		world.setBlockAndMetadata(i + 5, j + 0, k + 14, Block.planks.blockID, 3);
		world.setBlockAndMetadata(i + 5, j + 0, k + 15, Block.planks.blockID, 3);
		world.setBlockAndMetadata(i + 5, j + 0, k + 16, Block.planks.blockID, 3);
		world.setBlock(i + 5, j + 0, k + 17, Block.brick.blockID);
		world.setBlock(i + 5, j + 0, k + 18, Block.netherrack.blockID);
		world.setBlock(i + 5, j + 0, k + 19, Block.netherrack.blockID);
		world.setBlock(i + 5, j + 0, k + 20, Block.netherrack.blockID);
		world.setBlock(i + 5, j + 0, k + 21, Block.netherrack.blockID);
		world.setBlock(i + 5, j + 0, k + 22, Block.netherrack.blockID);
		world.setBlock(i + 5, j + 0, k + 23, Block.dirt.blockID);
		world.setBlock(i + 5, j + 0, k + 24, Block.grass.blockID);
		world.setBlock(i + 5, j + 1, k + 1, Block.stoneBrick.blockID);
		world.setBlock(i + 5, j + 1, k + 15, Block.fenceIron.blockID);
		world.setBlockAndMetadata(i + 5, j + 1, k + 18, Block.fire.blockID, 15);
		world.setBlockAndMetadata(i + 5, j + 1, k + 19, Block.fire.blockID, 15);
		world.setBlockAndMetadata(i + 5, j + 1, k + 20, Block.fire.blockID, 15);
		world.setBlockAndMetadata(i + 5, j + 1, k + 21, Block.fire.blockID, 15);
		world.setBlockAndMetadata(i + 5, j + 1, k + 22, Block.fire.blockID, 15);
		world.setBlock(i + 5, j + 1, k + 23, Block.cobblestone.blockID);
		world.setBlock(i + 5, j + 2, k + 1, Block.brick.blockID);
		world.setBlock(i + 5, j + 2, k + 15, Block.fenceIron.blockID);
		world.setBlock(i + 5, j + 2, k + 23, Block.cobblestone.blockID);
		world.setBlock(i + 5, j + 3, k + 1, Block.thinGlass.blockID);
		world.setBlock(i + 5, j + 3, k + 15, Block.cobblestone.blockID);
		world.setBlock(i + 5, j + 3, k + 16, Block.brick.blockID);
		world.setBlock(i + 5, j + 3, k + 17, Block.brick.blockID);
		world.setBlock(i + 5, j + 3, k + 23, Block.cobblestone.blockID);
		world.setBlock(i + 5, j + 4, k + 1, Block.thinGlass.blockID);
		world.setBlock(i + 5, j + 4, k + 15, Block.cobblestone.blockID);
		world.setBlock(i + 5, j + 4, k + 16, Block.brick.blockID);
		world.setBlock(i + 5, j + 4, k + 17, Block.brick.blockID);
		world.setBlock(i + 5, j + 4, k + 23, Block.cobblestone.blockID);
		world.setBlock(i + 5, j + 5, k + 1, Block.thinGlass.blockID);
		world.setBlock(i + 5, j + 5, k + 15, Block.cobblestone.blockID);
		world.setBlock(i + 5, j + 5, k + 16, Block.brick.blockID);
		world.setBlock(i + 5, j + 5, k + 17, Block.brick.blockID);
		world.setBlock(i + 5, j + 5, k + 23, Block.cobblestone.blockID);
		world.setBlock(i + 5, j + 6, k + 1, Block.thinGlass.blockID);
		world.setBlock(i + 5, j + 6, k + 15, Block.cobblestone.blockID);
		world.setBlock(i + 5, j + 6, k + 17, Block.brick.blockID);
		world.setBlock(i + 5, j + 6, k + 23, Block.cobblestone.blockID);
		world.setBlock(i + 5, j + 7, k + 1, Block.fenceIron.blockID);
		world.setBlock(i + 5, j + 7, k + 15, Block.cobblestone.blockID);
		world.setBlock(i + 5, j + 7, k + 17, Block.brick.blockID);
		world.setBlock(i + 5, j + 7, k + 23, Block.cobblestone.blockID);
		world.setBlock(i + 5, j + 8, k + 1, Block.thinGlass.blockID);
		world.setBlock(i + 5, j + 8, k + 15, Block.cobblestone.blockID);
		world.setBlock(i + 5, j + 8, k + 16, Block.cobblestone.blockID);
		world.setBlock(i + 5, j + 8, k + 17, Block.brick.blockID);
		world.setBlock(i + 5, j + 8, k + 22, Block.cobblestone.blockID);
		world.setBlock(i + 5, j + 9, k + 1, Block.brick.blockID);
		world.setBlock(i + 5, j + 9, k + 15, Block.brick.blockID);
		world.setBlock(i + 5, j + 9, k + 16, Block.cobblestone.blockID);
		world.setBlock(i + 5, j + 9, k + 17, Block.brick.blockID);
		world.setBlock(i + 5, j + 9, k + 22, Block.cobblestone.blockID);
		world.setBlock(i + 5, j + 10, k + 1, Block.brick.blockID);
		world.setBlock(i + 5, j + 10, k + 12, Block.brick.blockID);
		world.setBlock(i + 5, j + 10, k + 13, Block.brick.blockID);
		world.setBlock(i + 5, j + 10, k + 14, Block.brick.blockID);
		world.setBlock(i + 5, j + 10, k + 15, Block.stoneSingleSlab.blockID);
		world.setBlock(i + 5, j + 10, k + 16, Block.stoneDoubleSlab.blockID);
		world.setBlock(i + 5, j + 10, k + 17, Block.stoneSingleSlab.blockID);
		world.setBlock(i + 5, j + 10, k + 22, Block.cobblestone.blockID);
		world.setBlock(i + 5, j + 11, k + 1, Block.brick.blockID);
		world.setBlock(i + 5, j + 11, k + 9, Block.brick.blockID);
		world.setBlock(i + 5, j + 11, k + 10, Block.brick.blockID);
		world.setBlock(i + 5, j + 11, k + 11, Block.brick.blockID);
		world.setBlock(i + 5, j + 11, k + 12, Block.stoneSingleSlab.blockID);
		world.setBlock(i + 5, j + 11, k + 13, Block.stoneSingleSlab.blockID);
		world.setBlock(i + 5, j + 11, k + 14, Block.stoneSingleSlab.blockID);
		world.setBlock(i + 5, j + 11, k + 16, Block.cobblestone.blockID);
		world.setBlock(i + 5, j + 11, k + 22, Block.cobblestone.blockID);
		world.setBlock(i + 5, j + 12, k + 1, Block.brick.blockID);
		world.setBlock(i + 5, j + 12, k + 2, Block.brick.blockID);
		world.setBlock(i + 5, j + 12, k + 6, Block.brick.blockID);
		world.setBlock(i + 5, j + 12, k + 8, Block.brick.blockID);
		world.setBlock(i + 5, j + 12, k + 9, Block.stoneSingleSlab.blockID);
		world.setBlock(i + 5, j + 12, k + 10, Block.stoneSingleSlab.blockID);
		world.setBlock(i + 5, j + 12, k + 11, Block.stoneSingleSlab.blockID);
		world.setBlock(i + 5, j + 12, k + 16, Block.cobblestone.blockID);
		world.setBlock(i + 5, j + 12, k + 22, Block.cobblestone.blockID);
		world.setBlock(i + 5, j + 13, k + 1, Block.stoneSingleSlab.blockID);
		world.setBlock(i + 5, j + 13, k + 2, Block.stoneSingleSlab.blockID);
		world.setBlock(i + 5, j + 13, k + 3, Block.brick.blockID);
		world.setBlock(i + 5, j + 13, k + 4, Block.brick.blockID);
		world.setBlock(i + 5, j + 13, k + 5, Block.brick.blockID);
		world.setBlock(i + 5, j + 13, k + 6, Block.brick.blockID);
		world.setBlock(i + 5, j + 13, k + 8, Block.brick.blockID);
		world.setBlock(i + 5, j + 13, k + 16, Block.cobblestone.blockID);
		world.setBlock(i + 5, j + 13, k + 22, Block.cobblestone.blockID);
		world.setBlock(i + 5, j + 14, k + 3, Block.stoneSingleSlab.blockID);
		world.setBlock(i + 5, j + 14, k + 4, Block.stoneSingleSlab.blockID);
		world.setBlock(i + 5, j + 14, k + 5, Block.stoneSingleSlab.blockID);
		world.setBlock(i + 5, j + 14, k + 6, Block.brick.blockID);
		world.setBlock(i + 5, j + 14, k + 8, Block.brick.blockID);
		world.setBlock(i + 5, j + 14, k + 16, Block.cobblestone.blockID);
		world.setBlock(i + 5, j + 14, k + 22, Block.cobblestone.blockID);
		world.setBlock(i + 5, j + 15, k + 6, Block.brick.blockID);
		world.setBlock(i + 5, j + 15, k + 7, Block.brick.blockID);
		world.setBlock(i + 5, j + 15, k + 8, Block.brick.blockID);
		world.setBlock(i + 5, j + 15, k + 17, Block.cobblestone.blockID);
		world.setBlock(i + 5, j + 15, k + 21, Block.cobblestone.blockID);
		world.setBlock(i + 5, j + 16, k + 17, Block.cobblestone.blockID);
		world.setBlock(i + 5, j + 16, k + 21, Block.cobblestone.blockID);
		world.setBlock(i + 5, j + 17, k + 17, Block.cobblestone.blockID);
		world.setBlock(i + 5, j + 17, k + 21, Block.cobblestone.blockID);
		world.setBlock(i + 5, j + 18, k + 17, Block.cobblestone.blockID);
		world.setBlock(i + 5, j + 18, k + 21, Block.cobblestone.blockID);
		world.setBlock(i + 5, j + 19, k + 17, Block.cobblestone.blockID);
		world.setBlock(i + 5, j + 19, k + 21, Block.cobblestone.blockID);
		world.setBlock(i + 5, j + 20, k + 18, Block.cobblestone.blockID);
		world.setBlock(i + 5, j + 20, k + 19, Block.stoneBrick.blockID);
		world.setBlock(i + 5, j + 20, k + 20, Block.cobblestone.blockID);
		world.setBlock(i + 5, j + 21, k + 18, Block.cobblestone.blockID);
		world.setBlock(i + 5, j + 21, k + 20, Block.cobblestone.blockID);
		world.setBlock(i + 5, j + 22, k + 18, Block.cobblestone.blockID);
		world.setBlock(i + 5, j + 22, k + 20, Block.cobblestone.blockID);
		world.setBlock(i + 5, j + 23, k + 18, Block.cobblestone.blockID);
		world.setBlock(i + 5, j + 23, k + 20, Block.cobblestone.blockID);
		world.setBlock(i + 5, j + 24, k + 18, Block.cobblestone.blockID);
		world.setBlock(i + 5, j + 24, k + 19, Block.netherrack.blockID);
		world.setBlock(i + 5, j + 24, k + 20, Block.cobblestone.blockID);
		world.setBlock(i + 5, j + 25, k + 18, Block.cobblestone.blockID);
		world.setBlockAndMetadata(i + 5, j + 25, k + 19, Block.fire.blockID, 15);
		world.setBlock(i + 5, j + 25, k + 20, Block.cobblestone.blockID);
		world.setBlock(i + 6, j + 0, k + 0, Block.grass.blockID);
		world.setBlock(i + 6, j + 0, k + 1, Block.dirt.blockID);
		world.setBlockAndMetadata(i + 6, j + 0, k + 2, Block.planks.blockID, 3);
		world.setBlockAndMetadata(i + 6, j + 0, k + 3, Block.planks.blockID, 3);
		world.setBlockAndMetadata(i + 6, j + 0, k + 4, Block.planks.blockID, 3);
		world.setBlockAndMetadata(i + 6, j + 0, k + 5, Block.planks.blockID, 3);
		world.setBlockAndMetadata(i + 6, j + 0, k + 6, Block.planks.blockID, 3);
		world.setBlockAndMetadata(i + 6, j + 0, k + 7, Block.planks.blockID, 3);
		world.setBlockAndMetadata(i + 6, j + 0, k + 8, Block.planks.blockID, 3);
		world.setBlockAndMetadata(i + 6, j + 0, k + 9, Block.planks.blockID, 3);
		world.setBlockAndMetadata(i + 6, j + 0, k + 10, Block.planks.blockID, 3);
		world.setBlockAndMetadata(i + 6, j + 0, k + 11, Block.planks.blockID, 3);
		world.setBlockAndMetadata(i + 6, j + 0, k + 12, Block.planks.blockID, 3);
		world.setBlockAndMetadata(i + 6, j + 0, k + 13, Block.planks.blockID, 3);
		world.setBlockAndMetadata(i + 6, j + 0, k + 14, Block.planks.blockID, 3);
		world.setBlockAndMetadata(i + 6, j + 0, k + 15, Block.planks.blockID, 3);
		world.setBlockAndMetadata(i + 6, j + 0, k + 16, Block.planks.blockID, 3);
		world.setBlock(i + 6, j + 0, k + 17, Block.dirt.blockID);
		world.setBlock(i + 6, j + 0, k + 18, Block.netherrack.blockID);
		world.setBlock(i + 6, j + 0, k + 19, Block.netherrack.blockID);
		world.setBlock(i + 6, j + 0, k + 20, Block.netherrack.blockID);
		world.setBlock(i + 6, j + 0, k + 21, Block.netherrack.blockID);
		world.setBlock(i + 6, j + 0, k + 22, Block.dirt.blockID);
		world.setBlock(i + 6, j + 0, k + 23, Block.dirt.blockID);
		world.setBlock(i + 6, j + 0, k + 24, Block.grass.blockID);
		world.setBlock(i + 6, j + 1, k + 1, Block.stoneBrick.blockID);
		world.setBlock(i + 6, j + 1, k + 15, Block.cobblestone.blockID);
		world.setBlock(i + 6, j + 1, k + 16, Block.cobblestone.blockID);
		world.setBlock(i + 6, j + 1, k + 17, Block.brick.blockID);
		world.setBlockAndMetadata(i + 6, j + 1, k + 18, Block.fire.blockID, 15);
		world.setBlockAndMetadata(i + 6, j + 1, k + 19, Block.fire.blockID, 15);
		world.setBlockAndMetadata(i + 6, j + 1, k + 20, Block.fire.blockID, 15);
		world.setBlockAndMetadata(i + 6, j + 1, k + 21, Block.fire.blockID, 15);
		world.setBlock(i + 6, j + 1, k + 22, Block.cobblestone.blockID);
		world.setBlock(i + 6, j + 1, k + 23, Block.cobblestone.blockID);
		world.setBlock(i + 6, j + 2, k + 1, Block.brick.blockID);
		world.setBlock(i + 6, j + 2, k + 15, Block.cobblestone.blockID);
		world.setBlock(i + 6, j + 2, k + 16, Block.cobblestone.blockID);
		world.setBlock(i + 6, j + 2, k + 17, Block.brick.blockID);
		world.setBlock(i + 6, j + 2, k + 22, Block.cobblestone.blockID);
		world.setBlock(i + 6, j + 2, k + 23, Block.cobblestone.blockID);
		world.setBlock(i + 6, j + 3, k + 1, Block.brick.blockID);
		world.setBlock(i + 6, j + 3, k + 15, Block.cobblestone.blockID);
		world.setBlock(i + 6, j + 3, k + 16, Block.cobblestone.blockID);
		world.setBlock(i + 6, j + 3, k + 17, Block.brick.blockID);
		world.setBlock(i + 6, j + 3, k + 22, Block.cobblestone.blockID);
		world.setBlock(i + 6, j + 3, k + 23, Block.cobblestone.blockID);
		world.setBlock(i + 6, j + 4, k + 1, Block.brick.blockID);
		world.setBlock(i + 6, j + 4, k + 15, Block.cobblestone.blockID);
		world.setBlock(i + 6, j + 4, k + 16, Block.cobblestone.blockID);
		world.setBlock(i + 6, j + 4, k + 17, Block.brick.blockID);
		world.setBlock(i + 6, j + 4, k + 22, Block.cobblestone.blockID);
		world.setBlock(i + 6, j + 4, k + 23, Block.cobblestone.blockID);
		world.setBlock(i + 6, j + 5, k + 1, Block.brick.blockID);
		world.setBlock(i + 6, j + 5, k + 15, Block.cobblestone.blockID);
		world.setBlock(i + 6, j + 5, k + 16, Block.cobblestone.blockID);
		world.setBlock(i + 6, j + 5, k + 17, Block.brick.blockID);
		world.setBlock(i + 6, j + 5, k + 22, Block.cobblestone.blockID);
		world.setBlock(i + 6, j + 5, k + 23, Block.cobblestone.blockID);
		world.setBlock(i + 6, j + 6, k + 1, Block.brick.blockID);
		world.setBlock(i + 6, j + 6, k + 15, Block.cobblestone.blockID);
		world.setBlock(i + 6, j + 6, k + 16, Block.cobblestone.blockID);
		world.setBlock(i + 6, j + 6, k + 17, Block.brick.blockID);
		world.setBlock(i + 6, j + 6, k + 22, Block.cobblestone.blockID);
		world.setBlock(i + 6, j + 6, k + 23, Block.cobblestone.blockID);
		world.setBlock(i + 6, j + 7, k + 1, Block.brick.blockID);
		world.setBlock(i + 6, j + 7, k + 15, Block.cobblestone.blockID);
		world.setBlock(i + 6, j + 7, k + 16, Block.cobblestone.blockID);
		world.setBlock(i + 6, j + 7, k + 17, Block.brick.blockID);
		world.setBlock(i + 6, j + 7, k + 22, Block.cobblestone.blockID);
		world.setBlock(i + 6, j + 7, k + 23, Block.cobblestone.blockID);
		world.setBlock(i + 6, j + 8, k + 1, Block.brick.blockID);
		world.setBlock(i + 6, j + 8, k + 16, Block.cobblestone.blockID);
		world.setBlock(i + 6, j + 8, k + 17, Block.brick.blockID);
		world.setBlock(i + 6, j + 8, k + 21, Block.cobblestone.blockID);
		world.setBlock(i + 6, j + 9, k + 1, Block.brick.blockID);
		world.setBlock(i + 6, j + 9, k + 15, Block.brick.blockID);
		world.setBlock(i + 6, j + 9, k + 16, Block.brick.blockID);
		world.setBlock(i + 6, j + 9, k + 17, Block.brick.blockID);
		world.setBlock(i + 6, j + 9, k + 21, Block.cobblestone.blockID);
		world.setBlock(i + 6, j + 10, k + 1, Block.brick.blockID);
		world.setBlock(i + 6, j + 10, k + 12, Block.brick.blockID);
		world.setBlock(i + 6, j + 10, k + 13, Block.brick.blockID);
		world.setBlock(i + 6, j + 10, k + 14, Block.brick.blockID);
		world.setBlock(i + 6, j + 10, k + 15, Block.stoneSingleSlab.blockID);
		world.setBlock(i + 6, j + 10, k + 16, Block.stoneSingleSlab.blockID);
		world.setBlock(i + 6, j + 10, k + 17, Block.stoneDoubleSlab.blockID);
		world.setBlock(i + 6, j + 10, k + 21, Block.cobblestone.blockID);
		world.setBlock(i + 6, j + 11, k + 1, Block.brick.blockID);
		world.setBlock(i + 6, j + 11, k + 9, Block.brick.blockID);
		world.setBlock(i + 6, j + 11, k + 10, Block.brick.blockID);
		world.setBlock(i + 6, j + 11, k + 11, Block.brick.blockID);
		world.setBlock(i + 6, j + 11, k + 12, Block.stoneSingleSlab.blockID);
		world.setBlock(i + 6, j + 11, k + 13, Block.stoneSingleSlab.blockID);
		world.setBlock(i + 6, j + 11, k + 14, Block.stoneSingleSlab.blockID);
		world.setBlock(i + 6, j + 11, k + 17, Block.cobblestone.blockID);
		world.setBlock(i + 6, j + 11, k + 21, Block.cobblestone.blockID);
		world.setBlock(i + 6, j + 12, k + 1, Block.brick.blockID);
		world.setBlock(i + 6, j + 12, k + 2, Block.brick.blockID);
		world.setBlock(i + 6, j + 12, k + 6, Block.brick.blockID);
		world.setBlock(i + 6, j + 12, k + 8, Block.brick.blockID);
		world.setBlock(i + 6, j + 12, k + 9, Block.stoneSingleSlab.blockID);
		world.setBlock(i + 6, j + 12, k + 10, Block.stoneSingleSlab.blockID);
		world.setBlock(i + 6, j + 12, k + 11, Block.stoneSingleSlab.blockID);
		world.setBlock(i + 6, j + 12, k + 17, Block.cobblestone.blockID);
		world.setBlock(i + 6, j + 12, k + 21, Block.cobblestone.blockID);
		world.setBlock(i + 6, j + 13, k + 1, Block.stoneSingleSlab.blockID);
		world.setBlock(i + 6, j + 13, k + 2, Block.stoneSingleSlab.blockID);
		world.setBlock(i + 6, j + 13, k + 3, Block.brick.blockID);
		world.setBlock(i + 6, j + 13, k + 4, Block.brick.blockID);
		world.setBlock(i + 6, j + 13, k + 5, Block.brick.blockID);
		world.setBlock(i + 6, j + 13, k + 6, Block.brick.blockID);
		world.setBlock(i + 6, j + 13, k + 8, Block.glass.blockID);
		world.setBlock(i + 6, j + 13, k + 17, Block.cobblestone.blockID);
		world.setBlock(i + 6, j + 13, k + 21, Block.cobblestone.blockID);
		world.setBlock(i + 6, j + 14, k + 3, Block.stoneSingleSlab.blockID);
		world.setBlock(i + 6, j + 14, k + 4, Block.stoneSingleSlab.blockID);
		world.setBlock(i + 6, j + 14, k + 5, Block.stoneSingleSlab.blockID);
		world.setBlock(i + 6, j + 14, k + 6, Block.brick.blockID);
		world.setBlock(i + 6, j + 14, k + 8, Block.glass.blockID);
		world.setBlock(i + 6, j + 14, k + 17, Block.cobblestone.blockID);
		world.setBlock(i + 6, j + 14, k + 21, Block.cobblestone.blockID);
		world.setBlock(i + 6, j + 15, k + 6, Block.brick.blockID);
		world.setBlock(i + 6, j + 15, k + 7, Block.brick.blockID);
		world.setBlock(i + 6, j + 15, k + 8, Block.brick.blockID);
		world.setBlock(i + 6, j + 15, k + 18, Block.cobblestone.blockID);
		world.setBlock(i + 6, j + 15, k + 20, Block.cobblestone.blockID);
		world.setBlock(i + 6, j + 16, k + 18, Block.cobblestone.blockID);
		world.setBlock(i + 6, j + 16, k + 20, Block.cobblestone.blockID);
		world.setBlock(i + 6, j + 17, k + 18, Block.cobblestone.blockID);
		world.setBlock(i + 6, j + 17, k + 20, Block.cobblestone.blockID);
		world.setBlock(i + 6, j + 18, k + 18, Block.cobblestone.blockID);
		world.setBlock(i + 6, j + 18, k + 20, Block.cobblestone.blockID);
		world.setBlock(i + 6, j + 19, k + 18, Block.cobblestone.blockID);
		world.setBlock(i + 6, j + 19, k + 20, Block.cobblestone.blockID);
		world.setBlock(i + 6, j + 20, k + 19, Block.cobblestone.blockID);
		world.setBlock(i + 6, j + 21, k + 19, Block.cobblestone.blockID);
		world.setBlock(i + 6, j + 22, k + 19, Block.cobblestone.blockID);
		world.setBlock(i + 6, j + 23, k + 19, Block.cobblestone.blockID);
		world.setBlock(i + 6, j + 24, k + 19, Block.cobblestone.blockID);
		world.setBlock(i + 6, j + 25, k + 19, Block.cobblestone.blockID);
		world.setBlock(i + 7, j + 0, k + 0, Block.grass.blockID);
		world.setBlock(i + 7, j + 0, k + 1, Block.dirt.blockID);
		world.setBlockAndMetadata(i + 7, j + 0, k + 2, Block.planks.blockID, 3);
		world.setBlockAndMetadata(i + 7, j + 0, k + 3, Block.planks.blockID, 3);
		world.setBlockAndMetadata(i + 7, j + 0, k + 4, Block.planks.blockID, 3);
		world.setBlockAndMetadata(i + 7, j + 0, k + 5, Block.planks.blockID, 3);
		world.setBlockAndMetadata(i + 7, j + 0, k + 6, Block.planks.blockID, 3);
		world.setBlockAndMetadata(i + 7, j + 0, k + 7, Block.planks.blockID, 3);
		world.setBlockAndMetadata(i + 7, j + 0, k + 8, Block.planks.blockID, 3);
		world.setBlockAndMetadata(i + 7, j + 0, k + 9, Block.planks.blockID, 3);
		world.setBlockAndMetadata(i + 7, j + 0, k + 10, Block.planks.blockID, 3);
		world.setBlockAndMetadata(i + 7, j + 0, k + 11, Block.planks.blockID, 3);
		world.setBlockAndMetadata(i + 7, j + 0, k + 12, Block.planks.blockID, 3);
		world.setBlockAndMetadata(i + 7, j + 0, k + 13, Block.planks.blockID, 3);
		world.setBlockAndMetadata(i + 7, j + 0, k + 14, Block.planks.blockID, 3);
		world.setBlockAndMetadata(i + 7, j + 0, k + 15, Block.planks.blockID, 3);
		world.setBlockAndMetadata(i + 7, j + 0, k + 16, Block.planks.blockID, 3);
		world.setBlock(i + 7, j + 0, k + 17, Block.dirt.blockID);
		world.setBlock(i + 7, j + 0, k + 18, Block.netherrack.blockID);
		world.setBlock(i + 7, j + 0, k + 19, Block.netherrack.blockID);
		world.setBlock(i + 7, j + 0, k + 20, Block.netherrack.blockID);
		world.setBlock(i + 7, j + 0, k + 21, Block.dirt.blockID);
		world.setBlock(i + 7, j + 0, k + 22, Block.dirt.blockID);
		world.setBlock(i + 7, j + 0, k + 23, Block.grass.blockID);
		world.setBlock(i + 7, j + 0, k + 24, Block.grass.blockID);
		world.setBlock(i + 7, j + 1, k + 1, Block.stoneBrick.blockID);
		world.setBlock(i + 7, j + 1, k + 15, Block.dirt.blockID);
		world.setBlock(i + 7, j + 1, k + 16, Block.cobblestone.blockID);
		world.setBlock(i + 7, j + 1, k + 17, Block.brick.blockID);
		world.setBlockAndMetadata(i + 7, j + 1, k + 18, Block.fire.blockID, 15);
		world.setBlockAndMetadata(i + 7, j + 1, k + 19, Block.fire.blockID, 15);
		world.setBlockAndMetadata(i + 7, j + 1, k + 20, Block.fire.blockID, 15);
		world.setBlock(i + 7, j + 1, k + 21, Block.cobblestone.blockID);
		world.setBlock(i + 7, j + 1, k + 22, Block.cobblestone.blockID);
		world.setBlock(i + 7, j + 2, k + 1, Block.brick.blockID);
		world.setBlock(i + 7, j + 2, k + 16, Block.cobblestone.blockID);
		world.setBlock(i + 7, j + 2, k + 17, Block.brick.blockID);
		world.setBlock(i + 7, j + 2, k + 21, Block.cobblestone.blockID);
		world.setBlock(i + 7, j + 2, k + 22, Block.cobblestone.blockID);
		world.setBlock(i + 7, j + 3, k + 1, Block.brick.blockID);
		world.setBlock(i + 7, j + 3, k + 16, Block.cobblestone.blockID);
		world.setBlock(i + 7, j + 3, k + 17, Block.brick.blockID);
		world.setBlock(i + 7, j + 3, k + 21, Block.cobblestone.blockID);
		world.setBlock(i + 7, j + 3, k + 22, Block.cobblestone.blockID);
		world.setBlock(i + 7, j + 4, k + 1, Block.brick.blockID);
		world.setBlock(i + 7, j + 4, k + 15, Block.stoneBrick.blockID);
		world.setBlock(i + 7, j + 4, k + 16, Block.cobblestone.blockID);
		world.setBlock(i + 7, j + 4, k + 17, Block.brick.blockID);
		world.setBlock(i + 7, j + 4, k + 21, Block.cobblestone.blockID);
		world.setBlock(i + 7, j + 4, k + 22, Block.cobblestone.blockID);
		world.setBlock(i + 7, j + 5, k + 1, Block.brick.blockID);
		world.setBlock(i + 7, j + 5, k + 16, Block.cobblestone.blockID);
		world.setBlock(i + 7, j + 5, k + 17, Block.brick.blockID);
		world.setBlock(i + 7, j + 5, k + 21, Block.cobblestone.blockID);
		world.setBlock(i + 7, j + 5, k + 22, Block.cobblestone.blockID);
		world.setBlock(i + 7, j + 6, k + 1, Block.brick.blockID);
		world.setBlock(i + 7, j + 6, k + 16, Block.cobblestone.blockID);
		world.setBlock(i + 7, j + 6, k + 17, Block.brick.blockID);
		world.setBlock(i + 7, j + 6, k + 21, Block.cobblestone.blockID);
		world.setBlock(i + 7, j + 6, k + 22, Block.cobblestone.blockID);
		world.setBlock(i + 7, j + 7, k + 1, Block.brick.blockID);
		world.setBlock(i + 7, j + 7, k + 16, Block.cobblestone.blockID);
		world.setBlock(i + 7, j + 7, k + 17, Block.brick.blockID);
		world.setBlock(i + 7, j + 7, k + 21, Block.cobblestone.blockID);
		world.setBlock(i + 7, j + 7, k + 22, Block.cobblestone.blockID);
		world.setBlock(i + 7, j + 8, k + 1, Block.brick.blockID);
		world.setBlock(i + 7, j + 8, k + 17, Block.brick.blockID);
		world.setBlock(i + 7, j + 8, k + 18, Block.cobblestone.blockID);
		world.setBlock(i + 7, j + 8, k + 20, Block.cobblestone.blockID);
		world.setBlock(i + 7, j + 9, k + 1, Block.brick.blockID);
		world.setBlock(i + 7, j + 9, k + 15, Block.brick.blockID);
		world.setBlock(i + 7, j + 9, k + 16, Block.brick.blockID);
		world.setBlock(i + 7, j + 9, k + 17, Block.brick.blockID);
		world.setBlock(i + 7, j + 9, k + 18, Block.cobblestone.blockID);
		world.setBlock(i + 7, j + 9, k + 20, Block.cobblestone.blockID);
		world.setBlock(i + 7, j + 10, k + 1, Block.brick.blockID);
		world.setBlock(i + 7, j + 10, k + 12, Block.brick.blockID);
		world.setBlock(i + 7, j + 10, k + 13, Block.brick.blockID);
		world.setBlock(i + 7, j + 10, k + 14, Block.brick.blockID);
		world.setBlock(i + 7, j + 10, k + 15, Block.stoneSingleSlab.blockID);
		world.setBlock(i + 7, j + 10, k + 16, Block.stoneSingleSlab.blockID);
		world.setBlock(i + 7, j + 10, k + 17, Block.stoneSingleSlab.blockID);
		world.setBlock(i + 7, j + 10, k + 18, Block.cobblestone.blockID);
		world.setBlock(i + 7, j + 10, k + 20, Block.cobblestone.blockID);
		world.setBlock(i + 7, j + 11, k + 1, Block.brick.blockID);
		world.setBlock(i + 7, j + 11, k + 9, Block.brick.blockID);
		world.setBlock(i + 7, j + 11, k + 10, Block.brick.blockID);
		world.setBlock(i + 7, j + 11, k + 11, Block.brick.blockID);
		world.setBlock(i + 7, j + 11, k + 12, Block.stoneSingleSlab.blockID);
		world.setBlock(i + 7, j + 11, k + 13, Block.stoneSingleSlab.blockID);
		world.setBlock(i + 7, j + 11, k + 14, Block.stoneSingleSlab.blockID);
		world.setBlock(i + 7, j + 11, k + 18, Block.cobblestone.blockID);
		world.setBlock(i + 7, j + 11, k + 20, Block.cobblestone.blockID);
		world.setBlock(i + 7, j + 12, k + 1, Block.brick.blockID);
		world.setBlock(i + 7, j + 12, k + 2, Block.brick.blockID);
		world.setBlock(i + 7, j + 12, k + 6, Block.brick.blockID);
		world.setBlock(i + 7, j + 12, k + 8, Block.brick.blockID);
		world.setBlock(i + 7, j + 12, k + 9, Block.stoneSingleSlab.blockID);
		world.setBlock(i + 7, j + 12, k + 10, Block.stoneSingleSlab.blockID);
		world.setBlock(i + 7, j + 12, k + 11, Block.stoneSingleSlab.blockID);
		world.setBlock(i + 7, j + 12, k + 18, Block.cobblestone.blockID);
		world.setBlock(i + 7, j + 12, k + 20, Block.cobblestone.blockID);
		world.setBlock(i + 7, j + 13, k + 1, Block.stoneSingleSlab.blockID);
		world.setBlock(i + 7, j + 13, k + 2, Block.stoneSingleSlab.blockID);
		world.setBlock(i + 7, j + 13, k + 3, Block.brick.blockID);
		world.setBlock(i + 7, j + 13, k + 4, Block.brick.blockID);
		world.setBlock(i + 7, j + 13, k + 5, Block.brick.blockID);
		world.setBlock(i + 7, j + 13, k + 6, Block.brick.blockID);
		world.setBlock(i + 7, j + 13, k + 8, Block.glass.blockID);
		world.setBlock(i + 7, j + 13, k + 18, Block.cobblestone.blockID);
		world.setBlock(i + 7, j + 13, k + 20, Block.cobblestone.blockID);
		world.setBlock(i + 7, j + 14, k + 3, Block.stoneSingleSlab.blockID);
		world.setBlock(i + 7, j + 14, k + 4, Block.stoneSingleSlab.blockID);
		world.setBlock(i + 7, j + 14, k + 5, Block.stoneSingleSlab.blockID);
		world.setBlock(i + 7, j + 14, k + 6, Block.brick.blockID);
		world.setBlock(i + 7, j + 14, k + 8, Block.glass.blockID);
		world.setBlock(i + 7, j + 14, k + 18, Block.cobblestone.blockID);
		world.setBlock(i + 7, j + 14, k + 20, Block.cobblestone.blockID);
		world.setBlock(i + 7, j + 15, k + 6, Block.brick.blockID);
		world.setBlock(i + 7, j + 15, k + 7, Block.brick.blockID);
		world.setBlock(i + 7, j + 15, k + 8, Block.brick.blockID);
		world.setBlock(i + 7, j + 15, k + 19, Block.cobblestone.blockID);
		world.setBlock(i + 7, j + 16, k + 19, Block.cobblestone.blockID);
		world.setBlock(i + 7, j + 17, k + 19, Block.cobblestone.blockID);
		world.setBlock(i + 7, j + 18, k + 19, Block.cobblestone.blockID);
		world.setBlock(i + 7, j + 19, k + 19, Block.cobblestone.blockID);
		world.setBlock(i + 8, j + 0, k + 0, Block.grass.blockID);
		world.setBlock(i + 8, j + 0, k + 1, Block.dirt.blockID);
		world.setBlockAndMetadata(i + 8, j + 0, k + 2, Block.planks.blockID, 3);
		world.setBlockAndMetadata(i + 8, j + 0, k + 3, Block.planks.blockID, 3);
		world.setBlockAndMetadata(i + 8, j + 0, k + 4, Block.planks.blockID, 3);
		world.setBlockAndMetadata(i + 8, j + 0, k + 5, Block.planks.blockID, 3);
		world.setBlockAndMetadata(i + 8, j + 0, k + 6, Block.planks.blockID, 3);
		world.setBlockAndMetadata(i + 8, j + 0, k + 7, Block.planks.blockID, 3);
		world.setBlockAndMetadata(i + 8, j + 0, k + 8, Block.planks.blockID, 3);
		world.setBlockAndMetadata(i + 8, j + 0, k + 9, Block.planks.blockID, 3);
		world.setBlockAndMetadata(i + 8, j + 0, k + 10, Block.planks.blockID, 3);
		world.setBlockAndMetadata(i + 8, j + 0, k + 11, Block.planks.blockID, 3);
		world.setBlockAndMetadata(i + 8, j + 0, k + 12, Block.planks.blockID, 3);
		world.setBlockAndMetadata(i + 8, j + 0, k + 13, Block.planks.blockID, 3);
		world.setBlockAndMetadata(i + 8, j + 0, k + 14, Block.planks.blockID, 3);
		world.setBlockAndMetadata(i + 8, j + 0, k + 15, Block.planks.blockID, 3);
		world.setBlockAndMetadata(i + 8, j + 0, k + 16, Block.planks.blockID, 3);
		world.setBlock(i + 8, j + 0, k + 17, Block.dirt.blockID);
		world.setBlock(i + 8, j + 0, k + 18, Block.dirt.blockID);
		world.setBlock(i + 8, j + 0, k + 19, Block.netherrack.blockID);
		world.setBlock(i + 8, j + 0, k + 20, Block.dirt.blockID);
		world.setBlock(i + 8, j + 0, k + 21, Block.dirt.blockID);
		world.setBlock(i + 8, j + 0, k + 22, Block.grass.blockID);
		world.setBlock(i + 8, j + 0, k + 23, Block.grass.blockID);
		world.setBlock(i + 8, j + 0, k + 24, Block.grass.blockID);
		world.setBlock(i + 8, j + 1, k + 1, Block.stoneBrick.blockID);
		world.setBlock(i + 8, j + 1, k + 16, Block.dirt.blockID);
		world.setBlock(i + 8, j + 1, k + 17, Block.stoneBrick.blockID);
		world.setBlock(i + 8, j + 1, k + 18, Block.cobblestone.blockID);
		world.setBlockAndMetadata(i + 8, j + 1, k + 19, Block.fire.blockID, 15);
		world.setBlock(i + 8, j + 1, k + 20, Block.cobblestone.blockID);
		world.setBlock(i + 8, j + 1, k + 21, Block.cobblestone.blockID);
		world.setBlock(i + 8, j + 2, k + 1, Block.brick.blockID);
		world.setBlock(i + 8, j + 2, k + 16, Block.dirt.blockID);
		world.setBlock(i + 8, j + 2, k + 17, Block.brick.blockID);
		world.setBlock(i + 8, j + 2, k + 18, Block.cobblestone.blockID);
		world.setBlock(i + 8, j + 2, k + 20, Block.cobblestone.blockID);
		world.setBlock(i + 8, j + 2, k + 21, Block.cobblestone.blockID);
		world.setBlock(i + 8, j + 3, k + 17, Block.brick.blockID);
		world.setBlock(i + 8, j + 3, k + 18, Block.cobblestone.blockID);
		world.setBlock(i + 8, j + 3, k + 20, Block.cobblestone.blockID);
		world.setBlock(i + 8, j + 3, k + 21, Block.cobblestone.blockID);
		world.setBlock(i + 8, j + 4, k + 1, Block.thinGlass.blockID);
		world.setBlock(i + 8, j + 4, k + 15, Block.stoneBrick.blockID);
		world.setBlock(i + 8, j + 4, k + 16, Block.stoneBrick.blockID);
		world.setBlock(i + 8, j + 4, k + 17, Block.brick.blockID);
		world.setBlock(i + 8, j + 4, k + 18, Block.cobblestone.blockID);
		world.setBlock(i + 8, j + 4, k + 20, Block.cobblestone.blockID);
		world.setBlock(i + 8, j + 4, k + 21, Block.cobblestone.blockID);
		world.setBlock(i + 8, j + 5, k + 1, Block.thinGlass.blockID);
		world.setBlock(i + 8, j + 5, k + 17, Block.brick.blockID);
		world.setBlock(i + 8, j + 5, k + 18, Block.cobblestone.blockID);
		world.setBlock(i + 8, j + 5, k + 20, Block.cobblestone.blockID);
		world.setBlock(i + 8, j + 5, k + 21, Block.cobblestone.blockID);
		world.setBlock(i + 8, j + 6, k + 1, Block.thinGlass.blockID);
		world.setBlock(i + 8, j + 6, k + 17, Block.brick.blockID);
		world.setBlock(i + 8, j + 6, k + 18, Block.cobblestone.blockID);
		world.setBlock(i + 8, j + 6, k + 20, Block.cobblestone.blockID);
		world.setBlock(i + 8, j + 6, k + 21, Block.cobblestone.blockID);
		world.setBlock(i + 8, j + 7, k + 1, Block.thinGlass.blockID);
		world.setBlock(i + 8, j + 7, k + 17, Block.brick.blockID);
		world.setBlock(i + 8, j + 7, k + 18, Block.cobblestone.blockID);
		world.setBlock(i + 8, j + 7, k + 20, Block.cobblestone.blockID);
		world.setBlock(i + 8, j + 7, k + 21, Block.cobblestone.blockID);
		world.setBlock(i + 8, j + 8, k + 1, Block.thinGlass.blockID);
		world.setBlock(i + 8, j + 8, k + 17, Block.brick.blockID);
		world.setBlock(i + 8, j + 8, k + 19, Block.cobblestone.blockID);
		world.setBlock(i + 8, j + 9, k + 1, Block.brick.blockID);
		world.setBlock(i + 8, j + 9, k + 15, Block.brick.blockID);
		world.setBlock(i + 8, j + 9, k + 16, Block.brick.blockID);
		world.setBlock(i + 8, j + 9, k + 17, Block.brick.blockID);
		world.setBlock(i + 8, j + 9, k + 19, Block.cobblestone.blockID);
		world.setBlock(i + 8, j + 10, k + 1, Block.brick.blockID);
		world.setBlock(i + 8, j + 10, k + 12, Block.brick.blockID);
		world.setBlock(i + 8, j + 10, k + 13, Block.brick.blockID);
		world.setBlock(i + 8, j + 10, k + 14, Block.brick.blockID);
		world.setBlock(i + 8, j + 10, k + 15, Block.stoneSingleSlab.blockID);
		world.setBlock(i + 8, j + 10, k + 16, Block.stoneSingleSlab.blockID);
		world.setBlock(i + 8, j + 10, k + 17, Block.stoneSingleSlab.blockID);
		world.setBlock(i + 8, j + 10, k + 19, Block.cobblestone.blockID);
		world.setBlock(i + 8, j + 11, k + 1, Block.brick.blockID);
		world.setBlock(i + 8, j + 11, k + 9, Block.brick.blockID);
		world.setBlock(i + 8, j + 11, k + 10, Block.brick.blockID);
		world.setBlock(i + 8, j + 11, k + 11, Block.brick.blockID);
		world.setBlock(i + 8, j + 11, k + 12, Block.stoneSingleSlab.blockID);
		world.setBlock(i + 8, j + 11, k + 13, Block.stoneSingleSlab.blockID);
		world.setBlock(i + 8, j + 11, k + 14, Block.stoneSingleSlab.blockID);
		world.setBlock(i + 8, j + 11, k + 19, Block.cobblestone.blockID);
		world.setBlock(i + 8, j + 12, k + 1, Block.brick.blockID);
		world.setBlock(i + 8, j + 12, k + 2, Block.brick.blockID);
		world.setBlock(i + 8, j + 12, k + 6, Block.brick.blockID);
		world.setBlock(i + 8, j + 12, k + 8, Block.brick.blockID);
		world.setBlock(i + 8, j + 12, k + 9, Block.stoneSingleSlab.blockID);
		world.setBlock(i + 8, j + 12, k + 10, Block.stoneSingleSlab.blockID);
		world.setBlock(i + 8, j + 12, k + 11, Block.stoneSingleSlab.blockID);
		world.setBlock(i + 8, j + 12, k + 19, Block.cobblestone.blockID);
		world.setBlock(i + 8, j + 13, k + 1, Block.stoneSingleSlab.blockID);
		world.setBlock(i + 8, j + 13, k + 2, Block.stoneSingleSlab.blockID);
		world.setBlock(i + 8, j + 13, k + 3, Block.brick.blockID);
		world.setBlock(i + 8, j + 13, k + 4, Block.brick.blockID);
		world.setBlock(i + 8, j + 13, k + 5, Block.brick.blockID);
		world.setBlock(i + 8, j + 13, k + 6, Block.brick.blockID);
		world.setBlock(i + 8, j + 13, k + 8, Block.brick.blockID);
		world.setBlock(i + 8, j + 13, k + 19, Block.cobblestone.blockID);
		world.setBlock(i + 8, j + 14, k + 3, Block.stoneSingleSlab.blockID);
		world.setBlock(i + 8, j + 14, k + 4, Block.stoneSingleSlab.blockID);
		world.setBlock(i + 8, j + 14, k + 5, Block.stoneSingleSlab.blockID);
		world.setBlock(i + 8, j + 14, k + 6, Block.brick.blockID);
		world.setBlock(i + 8, j + 14, k + 8, Block.brick.blockID);
		world.setBlock(i + 8, j + 14, k + 19, Block.cobblestone.blockID);
		world.setBlock(i + 8, j + 15, k + 6, Block.brick.blockID);
		world.setBlock(i + 8, j + 15, k + 7, Block.brick.blockID);
		world.setBlock(i + 8, j + 15, k + 8, Block.brick.blockID);
		world.setBlock(i + 9, j + 0, k + 0, Block.grass.blockID);
		world.setBlock(i + 9, j + 0, k + 1, Block.dirt.blockID);
		world.setBlockAndMetadata(i + 9, j + 0, k + 2, Block.planks.blockID, 3);
		world.setBlockAndMetadata(i + 9, j + 0, k + 3, Block.planks.blockID, 3);
		world.setBlockAndMetadata(i + 9, j + 0, k + 4, Block.planks.blockID, 3);
		world.setBlockAndMetadata(i + 9, j + 0, k + 5, Block.planks.blockID, 3);
		world.setBlockAndMetadata(i + 9, j + 0, k + 6, Block.planks.blockID, 3);
		world.setBlockAndMetadata(i + 9, j + 0, k + 7, Block.planks.blockID, 3);
		world.setBlockAndMetadata(i + 9, j + 0, k + 8, Block.planks.blockID, 3);
		world.setBlockAndMetadata(i + 9, j + 0, k + 9, Block.planks.blockID, 3);
		world.setBlockAndMetadata(i + 9, j + 0, k + 10, Block.planks.blockID, 3);
		world.setBlockAndMetadata(i + 9, j + 0, k + 11, Block.planks.blockID, 3);
		world.setBlockAndMetadata(i + 9, j + 0, k + 12, Block.planks.blockID, 3);
		world.setBlockAndMetadata(i + 9, j + 0, k + 13, Block.planks.blockID, 3);
		world.setBlockAndMetadata(i + 9, j + 0, k + 14, Block.planks.blockID, 3);
		world.setBlockAndMetadata(i + 9, j + 0, k + 15, Block.planks.blockID, 3);
		world.setBlockAndMetadata(i + 9, j + 0, k + 16, Block.planks.blockID, 3);
		world.setBlock(i + 9, j + 0, k + 17, Block.dirt.blockID);
		world.setBlock(i + 9, j + 0, k + 18, Block.dirt.blockID);
		world.setBlock(i + 9, j + 0, k + 19, Block.dirt.blockID);
		world.setBlock(i + 9, j + 0, k + 20, Block.dirt.blockID);
		world.setBlock(i + 9, j + 0, k + 21, Block.grass.blockID);
		world.setBlock(i + 9, j + 0, k + 22, Block.grass.blockID);
		world.setBlock(i + 9, j + 0, k + 23, Block.grass.blockID);
		world.setBlock(i + 9, j + 0, k + 24, Block.grass.blockID);
		world.setBlock(i + 9, j + 1, k + 1, Block.stoneBrick.blockID);
		world.setBlock(i + 9, j + 1, k + 17, Block.stoneBrick.blockID);
		world.setBlock(i + 9, j + 1, k + 18, Block.cobblestone.blockID);
		world.setBlock(i + 9, j + 1, k + 19, Block.cobblestone.blockID);
		world.setBlock(i + 9, j + 1, k + 20, Block.cobblestone.blockID);
		world.setBlock(i + 9, j + 2, k + 1, Block.brick.blockID);
		world.setBlock(i + 9, j + 2, k + 17, Block.brick.blockID);
		world.setBlock(i + 9, j + 2, k + 18, Block.cobblestone.blockID);
		world.setBlock(i + 9, j + 2, k + 19, Block.cobblestone.blockID);
		world.setBlock(i + 9, j + 2, k + 20, Block.cobblestone.blockID);
		world.setBlock(i + 9, j + 3, k + 1, Block.thinGlass.blockID);
		world.setBlock(i + 9, j + 3, k + 17, Block.brick.blockID);
		world.setBlock(i + 9, j + 3, k + 18, Block.cobblestone.blockID);
		world.setBlock(i + 9, j + 3, k + 19, Block.cobblestone.blockID);
		world.setBlock(i + 9, j + 3, k + 20, Block.cobblestone.blockID);
		world.setBlock(i + 9, j + 4, k + 1, Block.thinGlass.blockID);
		world.setBlock(i + 9, j + 4, k + 15, Block.stoneBrick.blockID);
		world.setBlock(i + 9, j + 4, k + 16, Block.stoneBrick.blockID);
		world.setBlock(i + 9, j + 4, k + 17, Block.brick.blockID);
		world.setBlock(i + 9, j + 4, k + 18, Block.cobblestone.blockID);
		world.setBlock(i + 9, j + 4, k + 19, Block.cobblestone.blockID);
		world.setBlock(i + 9, j + 4, k + 20, Block.cobblestone.blockID);
		world.setBlock(i + 9, j + 5, k + 1, Block.thinGlass.blockID);
		world.setBlock(i + 9, j + 5, k + 17, Block.brick.blockID);
		world.setBlock(i + 9, j + 5, k + 18, Block.cobblestone.blockID);
		world.setBlock(i + 9, j + 5, k + 19, Block.cobblestone.blockID);
		world.setBlock(i + 9, j + 5, k + 20, Block.cobblestone.blockID);
		world.setBlock(i + 9, j + 6, k + 1, Block.thinGlass.blockID);
		world.setBlock(i + 9, j + 6, k + 17, Block.brick.blockID);
		world.setBlock(i + 9, j + 6, k + 18, Block.cobblestone.blockID);
		world.setBlock(i + 9, j + 6, k + 19, Block.cobblestone.blockID);
		world.setBlock(i + 9, j + 6, k + 20, Block.cobblestone.blockID);
		world.setBlock(i + 9, j + 7, k + 1, Block.thinGlass.blockID);
		world.setBlock(i + 9, j + 7, k + 17, Block.brick.blockID);
		world.setBlock(i + 9, j + 7, k + 18, Block.cobblestone.blockID);
		world.setBlock(i + 9, j + 7, k + 19, Block.cobblestone.blockID);
		world.setBlock(i + 9, j + 7, k + 20, Block.cobblestone.blockID);
		world.setBlock(i + 9, j + 8, k + 17, Block.brick.blockID);
		world.setBlock(i + 9, j + 9, k + 1, Block.thinGlass.blockID);
		world.setBlock(i + 9, j + 9, k + 15, Block.brick.blockID);
		world.setBlock(i + 9, j + 9, k + 16, Block.brick.blockID);
		world.setBlock(i + 9, j + 9, k + 17, Block.brick.blockID);
		world.setBlock(i + 9, j + 10, k + 1, Block.brick.blockID);
		world.setBlock(i + 9, j + 10, k + 12, Block.brick.blockID);
		world.setBlock(i + 9, j + 10, k + 13, Block.brick.blockID);
		world.setBlock(i + 9, j + 10, k + 14, Block.brick.blockID);
		world.setBlock(i + 9, j + 10, k + 15, Block.stoneSingleSlab.blockID);
		world.setBlock(i + 9, j + 10, k + 16, Block.stoneSingleSlab.blockID);
		world.setBlock(i + 9, j + 10, k + 17, Block.stoneSingleSlab.blockID);
		world.setBlock(i + 9, j + 11, k + 1, Block.brick.blockID);
		world.setBlock(i + 9, j + 11, k + 9, Block.brick.blockID);
		world.setBlock(i + 9, j + 11, k + 10, Block.brick.blockID);
		world.setBlock(i + 9, j + 11, k + 11, Block.brick.blockID);
		world.setBlock(i + 9, j + 11, k + 12, Block.stoneSingleSlab.blockID);
		world.setBlock(i + 9, j + 11, k + 13, Block.stoneSingleSlab.blockID);
		world.setBlock(i + 9, j + 11, k + 14, Block.stoneSingleSlab.blockID);
		world.setBlock(i + 9, j + 12, k + 1, Block.brick.blockID);
		world.setBlock(i + 9, j + 12, k + 2, Block.brick.blockID);
		world.setBlock(i + 9, j + 12, k + 6, Block.brick.blockID);
		world.setBlock(i + 9, j + 12, k + 8, Block.brick.blockID);
		world.setBlock(i + 9, j + 12, k + 9, Block.stoneSingleSlab.blockID);
		world.setBlock(i + 9, j + 12, k + 10, Block.stoneSingleSlab.blockID);
		world.setBlock(i + 9, j + 12, k + 11, Block.stoneSingleSlab.blockID);
		world.setBlock(i + 9, j + 13, k + 1, Block.stoneSingleSlab.blockID);
		world.setBlock(i + 9, j + 13, k + 2, Block.stoneSingleSlab.blockID);
		world.setBlock(i + 9, j + 13, k + 3, Block.brick.blockID);
		world.setBlock(i + 9, j + 13, k + 4, Block.brick.blockID);
		world.setBlock(i + 9, j + 13, k + 5, Block.brick.blockID);
		world.setBlock(i + 9, j + 13, k + 6, Block.brick.blockID);
		world.setBlock(i + 9, j + 13, k + 8, Block.glass.blockID);
		world.setBlock(i + 9, j + 14, k + 3, Block.stoneSingleSlab.blockID);
		world.setBlock(i + 9, j + 14, k + 4, Block.stoneSingleSlab.blockID);
		world.setBlock(i + 9, j + 14, k + 5, Block.stoneSingleSlab.blockID);
		world.setBlock(i + 9, j + 14, k + 6, Block.brick.blockID);
		world.setBlock(i + 9, j + 14, k + 8, Block.glass.blockID);
		world.setBlock(i + 9, j + 15, k + 6, Block.brick.blockID);
		world.setBlock(i + 9, j + 15, k + 7, Block.brick.blockID);
		world.setBlock(i + 9, j + 15, k + 8, Block.brick.blockID);
		world.setBlock(i + 10, j + 0, k + 0, Block.grass.blockID);
		world.setBlock(i + 10, j + 0, k + 1, Block.dirt.blockID);
		world.setBlockAndMetadata(i + 10, j + 0, k + 2, Block.planks.blockID, 3);
		world.setBlockAndMetadata(i + 10, j + 0, k + 3, Block.planks.blockID, 3);
		world.setBlockAndMetadata(i + 10, j + 0, k + 4, Block.planks.blockID, 3);
		world.setBlockAndMetadata(i + 10, j + 0, k + 5, Block.planks.blockID, 3);
		world.setBlockAndMetadata(i + 10, j + 0, k + 6, Block.planks.blockID, 3);
		world.setBlockAndMetadata(i + 10, j + 0, k + 7, Block.planks.blockID, 3);
		world.setBlockAndMetadata(i + 10, j + 0, k + 8, Block.planks.blockID, 3);
		world.setBlockAndMetadata(i + 10, j + 0, k + 9, Block.planks.blockID, 3);
		world.setBlockAndMetadata(i + 10, j + 0, k + 10, Block.planks.blockID, 3);
		world.setBlockAndMetadata(i + 10, j + 0, k + 11, Block.planks.blockID, 3);
		world.setBlockAndMetadata(i + 10, j + 0, k + 12, Block.planks.blockID, 3);
		world.setBlockAndMetadata(i + 10, j + 0, k + 13, Block.planks.blockID, 3);
		world.setBlockAndMetadata(i + 10, j + 0, k + 14, Block.planks.blockID, 3);
		world.setBlockAndMetadata(i + 10, j + 0, k + 15, Block.planks.blockID, 3);
		world.setBlockAndMetadata(i + 10, j + 0, k + 16, Block.planks.blockID, 3);
		world.setBlock(i + 10, j + 0, k + 17, Block.dirt.blockID);
		world.setBlock(i + 10, j + 0, k + 18, Block.grass.blockID);
		world.setBlock(i + 10, j + 0, k + 19, Block.grass.blockID);
		world.setBlock(i + 10, j + 0, k + 20, Block.grass.blockID);
		world.setBlock(i + 10, j + 0, k + 21, Block.grass.blockID);
		world.setBlock(i + 10, j + 0, k + 22, Block.grass.blockID);
		world.setBlock(i + 10, j + 0, k + 23, Block.grass.blockID);
		world.setBlock(i + 10, j + 0, k + 24, Block.grass.blockID);
		world.setBlock(i + 10, j + 1, k + 1, Block.stoneBrick.blockID);
		world.setBlock(i + 10, j + 1, k + 17, Block.stoneBrick.blockID);
		world.setBlock(i + 10, j + 2, k + 1, Block.brick.blockID);
		world.setBlock(i + 10, j + 2, k + 17, Block.brick.blockID);
		world.setBlock(i + 10, j + 3, k + 1, Block.thinGlass.blockID);
		world.setBlock(i + 10, j + 3, k + 17, Block.brick.blockID);
		world.setBlock(i + 10, j + 4, k + 1, Block.thinGlass.blockID);
		world.setBlock(i + 10, j + 4, k + 15, Block.stoneBrick.blockID);
		world.setBlock(i + 10, j + 4, k + 16, Block.stoneBrick.blockID);
		world.setBlock(i + 10, j + 4, k + 17, Block.brick.blockID);
		world.setBlock(i + 10, j + 5, k + 1, Block.thinGlass.blockID);
		world.setBlock(i + 10, j + 5, k + 17, Block.brick.blockID);
		world.setBlock(i + 10, j + 6, k + 17, Block.thinGlass.blockID);
		world.setBlock(i + 10, j + 7, k + 1, Block.thinGlass.blockID);
		world.setBlock(i + 10, j + 7, k + 17, Block.thinGlass.blockID);
		world.setBlock(i + 10, j + 8, k + 1, Block.thinGlass.blockID);
		world.setBlock(i + 10, j + 8, k + 17, Block.brick.blockID);
		world.setBlock(i + 10, j + 9, k + 1, Block.brick.blockID);
		world.setBlock(i + 10, j + 9, k + 15, Block.brick.blockID);
		world.setBlock(i + 10, j + 9, k + 16, Block.brick.blockID);
		world.setBlock(i + 10, j + 9, k + 17, Block.brick.blockID);
		world.setBlock(i + 10, j + 10, k + 1, Block.brick.blockID);
		world.setBlock(i + 10, j + 10, k + 12, Block.brick.blockID);
		world.setBlock(i + 10, j + 10, k + 13, Block.brick.blockID);
		world.setBlock(i + 10, j + 10, k + 14, Block.brick.blockID);
		world.setBlock(i + 10, j + 10, k + 15, Block.stoneSingleSlab.blockID);
		world.setBlock(i + 10, j + 10, k + 16, Block.stoneSingleSlab.blockID);
		world.setBlock(i + 10, j + 10, k + 17, Block.stoneSingleSlab.blockID);
		world.setBlock(i + 10, j + 11, k + 1, Block.brick.blockID);
		world.setBlock(i + 10, j + 11, k + 9, Block.brick.blockID);
		world.setBlock(i + 10, j + 11, k + 10, Block.brick.blockID);
		world.setBlock(i + 10, j + 11, k + 11, Block.brick.blockID);
		world.setBlock(i + 10, j + 11, k + 12, Block.stoneSingleSlab.blockID);
		world.setBlock(i + 10, j + 11, k + 13, Block.stoneSingleSlab.blockID);
		world.setBlock(i + 10, j + 11, k + 14, Block.stoneSingleSlab.blockID);
		world.setBlock(i + 10, j + 12, k + 1, Block.brick.blockID);
		world.setBlock(i + 10, j + 12, k + 2, Block.brick.blockID);
		world.setBlock(i + 10, j + 12, k + 6, Block.brick.blockID);
		world.setBlock(i + 10, j + 12, k + 8, Block.brick.blockID);
		world.setBlock(i + 10, j + 12, k + 9, Block.stoneSingleSlab.blockID);
		world.setBlock(i + 10, j + 12, k + 10, Block.stoneSingleSlab.blockID);
		world.setBlock(i + 10, j + 12, k + 11, Block.stoneSingleSlab.blockID);
		world.setBlock(i + 10, j + 13, k + 1, Block.stoneSingleSlab.blockID);
		world.setBlock(i + 10, j + 13, k + 2, Block.stoneSingleSlab.blockID);
		world.setBlock(i + 10, j + 13, k + 3, Block.brick.blockID);
		world.setBlock(i + 10, j + 13, k + 4, Block.brick.blockID);
		world.setBlock(i + 10, j + 13, k + 5, Block.brick.blockID);
		world.setBlock(i + 10, j + 13, k + 6, Block.brick.blockID);
		world.setBlock(i + 10, j + 13, k + 8, Block.glass.blockID);
		world.setBlock(i + 10, j + 14, k + 3, Block.stoneSingleSlab.blockID);
		world.setBlock(i + 10, j + 14, k + 4, Block.stoneSingleSlab.blockID);
		world.setBlock(i + 10, j + 14, k + 5, Block.stoneSingleSlab.blockID);
		world.setBlock(i + 10, j + 14, k + 6, Block.brick.blockID);
		world.setBlock(i + 10, j + 14, k + 8, Block.glass.blockID);
		world.setBlock(i + 10, j + 15, k + 6, Block.brick.blockID);
		world.setBlock(i + 10, j + 15, k + 7, Block.brick.blockID);
		world.setBlock(i + 10, j + 15, k + 8, Block.brick.blockID);
		world.setBlock(i + 11, j + 0, k + 0, Block.grass.blockID);
		world.setBlock(i + 11, j + 0, k + 1, Block.dirt.blockID);
		world.setBlockAndMetadata(i + 11, j + 0, k + 2, Block.planks.blockID, 3);
		world.setBlockAndMetadata(i + 11, j + 0, k + 3, Block.planks.blockID, 3);
		world.setBlockAndMetadata(i + 11, j + 0, k + 4, Block.planks.blockID, 3);
		world.setBlockAndMetadata(i + 11, j + 0, k + 5, Block.planks.blockID, 3);
		world.setBlockAndMetadata(i + 11, j + 0, k + 6, Block.planks.blockID, 3);
		world.setBlockAndMetadata(i + 11, j + 0, k + 7, Block.planks.blockID, 3);
		world.setBlockAndMetadata(i + 11, j + 0, k + 8, Block.planks.blockID, 3);
		world.setBlockAndMetadata(i + 11, j + 0, k + 9, Block.planks.blockID, 3);
		world.setBlockAndMetadata(i + 11, j + 0, k + 10, Block.planks.blockID, 3);
		world.setBlockAndMetadata(i + 11, j + 0, k + 11, Block.planks.blockID, 3);
		world.setBlockAndMetadata(i + 11, j + 0, k + 12, Block.planks.blockID, 3);
		world.setBlockAndMetadata(i + 11, j + 0, k + 13, Block.planks.blockID, 3);
		world.setBlockAndMetadata(i + 11, j + 0, k + 14, Block.planks.blockID, 3);
		world.setBlockAndMetadata(i + 11, j + 0, k + 15, Block.planks.blockID, 3);
		world.setBlockAndMetadata(i + 11, j + 0, k + 16, Block.planks.blockID, 3);
		world.setBlock(i + 11, j + 0, k + 17, Block.dirt.blockID);
		world.setBlock(i + 11, j + 0, k + 18, Block.grass.blockID);
		world.setBlock(i + 11, j + 0, k + 19, Block.grass.blockID);
		world.setBlock(i + 11, j + 0, k + 20, Block.grass.blockID);
		world.setBlock(i + 11, j + 0, k + 21, Block.grass.blockID);
		world.setBlock(i + 11, j + 0, k + 22, Block.grass.blockID);
		world.setBlock(i + 11, j + 0, k + 23, Block.grass.blockID);
		world.setBlock(i + 11, j + 0, k + 24, Block.grass.blockID);
		world.setBlock(i + 11, j + 1, k + 1, Block.stoneBrick.blockID);
		world.setBlock(i + 11, j + 1, k + 17, Block.stoneBrick.blockID);
		world.setBlock(i + 11, j + 2, k + 1, Block.brick.blockID);
		world.setBlock(i + 11, j + 2, k + 17, Block.brick.blockID);
		world.setBlock(i + 11, j + 3, k + 1, Block.brick.blockID);
		world.setBlock(i + 11, j + 3, k + 17, Block.brick.blockID);
		world.setBlock(i + 11, j + 4, k + 1, Block.brick.blockID);
		world.setBlock(i + 11, j + 4, k + 15, Block.stoneBrick.blockID);
		world.setBlock(i + 11, j + 4, k + 16, Block.stoneBrick.blockID);
		world.setBlock(i + 11, j + 4, k + 17, Block.brick.blockID);
		world.setBlock(i + 11, j + 5, k + 1, Block.brick.blockID);
		
		//TODO
		if(rand.nextInt(100)<28){
			switch(rand.nextInt(4)){
				case 0:
					world.setBlock(i + 11, j + 5, k + 16, ModBlocks.zoroFurnaceBlock.blockID);
					break;
				case 1:
					world.setBlock(i + 11, j + 5, k + 16, ModBlocks.zoroGenBlock.blockID);
					break;
				case 2:
					world.setBlock(i + 11, j + 5, k + 16, ModBlocks.stearilliumGrinder.blockID);
					break;
				case 3:
					world.setBlock(i + 11, j + 5, k + 16, ModBlocks.triniumCore.blockID);
					break;	
			}
			
		}
		
		world.setBlock(i + 11, j + 5, k + 17, Block.brick.blockID);
		world.setBlock(i + 11, j + 6, k + 1, Block.brick.blockID);
		world.setBlock(i + 11, j + 6, k + 17, Block.brick.blockID);
		world.setBlock(i + 11, j + 7, k + 1, Block.brick.blockID);
		world.setBlock(i + 11, j + 7, k + 17, Block.brick.blockID);
		world.setBlock(i + 11, j + 8, k + 1, Block.brick.blockID);
		world.setBlock(i + 11, j + 8, k + 17, Block.brick.blockID);
		world.setBlock(i + 11, j + 9, k + 1, Block.brick.blockID);
		world.setBlock(i + 11, j + 9, k + 15, Block.brick.blockID);
		world.setBlock(i + 11, j + 9, k + 16, Block.brick.blockID);
		world.setBlock(i + 11, j + 9, k + 17, Block.brick.blockID);
		world.setBlock(i + 11, j + 10, k + 1, Block.brick.blockID);
		world.setBlock(i + 11, j + 10, k + 12, Block.brick.blockID);
		world.setBlock(i + 11, j + 10, k + 13, Block.brick.blockID);
		world.setBlock(i + 11, j + 10, k + 14, Block.brick.blockID);
		world.setBlock(i + 11, j + 10, k + 15, Block.stoneSingleSlab.blockID);
		world.setBlock(i + 11, j + 10, k + 16, Block.stoneSingleSlab.blockID);
		world.setBlock(i + 11, j + 10, k + 17, Block.stoneSingleSlab.blockID);
		world.setBlock(i + 11, j + 11, k + 1, Block.brick.blockID);
		world.setBlock(i + 11, j + 11, k + 9, Block.brick.blockID);
		world.setBlock(i + 11, j + 11, k + 10, Block.brick.blockID);
		world.setBlock(i + 11, j + 11, k + 11, Block.brick.blockID);
		world.setBlock(i + 11, j + 11, k + 12, Block.stoneSingleSlab.blockID);
		world.setBlock(i + 11, j + 11, k + 13, Block.stoneSingleSlab.blockID);
		world.setBlock(i + 11, j + 11, k + 14, Block.stoneSingleSlab.blockID);
		world.setBlock(i + 11, j + 12, k + 1, Block.brick.blockID);
		world.setBlock(i + 11, j + 12, k + 2, Block.brick.blockID);
		world.setBlock(i + 11, j + 12, k + 6, Block.brick.blockID);
		world.setBlock(i + 11, j + 12, k + 8, Block.brick.blockID);
		world.setBlock(i + 11, j + 12, k + 9, Block.stoneSingleSlab.blockID);
		world.setBlock(i + 11, j + 12, k + 10, Block.stoneSingleSlab.blockID);
		world.setBlock(i + 11, j + 12, k + 11, Block.stoneSingleSlab.blockID);
		world.setBlock(i + 11, j + 13, k + 1, Block.stoneSingleSlab.blockID);
		world.setBlock(i + 11, j + 13, k + 2, Block.stoneSingleSlab.blockID);
		world.setBlock(i + 11, j + 13, k + 3, Block.brick.blockID);
		world.setBlock(i + 11, j + 13, k + 4, Block.brick.blockID);
		world.setBlock(i + 11, j + 13, k + 5, Block.brick.blockID);
		world.setBlock(i + 11, j + 13, k + 6, Block.brick.blockID);
		world.setBlock(i + 11, j + 13, k + 8, Block.brick.blockID);
		world.setBlock(i + 11, j + 14, k + 3, Block.stoneSingleSlab.blockID);
		world.setBlock(i + 11, j + 14, k + 4, Block.stoneSingleSlab.blockID);
		world.setBlock(i + 11, j + 14, k + 5, Block.stoneSingleSlab.blockID);
		world.setBlock(i + 11, j + 14, k + 6, Block.brick.blockID);
		world.setBlock(i + 11, j + 14, k + 8, Block.brick.blockID);
		world.setBlock(i + 11, j + 15, k + 6, Block.brick.blockID);
		world.setBlock(i + 11, j + 15, k + 7, Block.brick.blockID);
		world.setBlock(i + 11, j + 15, k + 8, Block.brick.blockID);
		world.setBlock(i + 12, j + 0, k + 0, Block.grass.blockID);
		world.setBlock(i + 12, j + 0, k + 1, Block.dirt.blockID);
		world.setBlockAndMetadata(i + 12, j + 0, k + 2, Block.planks.blockID, 3);
		world.setBlockAndMetadata(i + 12, j + 0, k + 3, Block.planks.blockID, 3);
		world.setBlockAndMetadata(i + 12, j + 0, k + 4, Block.planks.blockID, 3);
		world.setBlockAndMetadata(i + 12, j + 0, k + 5, Block.planks.blockID, 3);
		world.setBlockAndMetadata(i + 12, j + 0, k + 6, Block.planks.blockID, 3);
		world.setBlockAndMetadata(i + 12, j + 0, k + 7, Block.planks.blockID, 3);
		world.setBlockAndMetadata(i + 12, j + 0, k + 8, Block.planks.blockID, 3);
		world.setBlockAndMetadata(i + 12, j + 0, k + 9, Block.planks.blockID, 3);
		world.setBlockAndMetadata(i + 12, j + 0, k + 10, Block.planks.blockID, 3);
		world.setBlockAndMetadata(i + 12, j + 0, k + 11, Block.planks.blockID, 3);
		world.setBlockAndMetadata(i + 12, j + 0, k + 12, Block.planks.blockID, 3);
		world.setBlockAndMetadata(i + 12, j + 0, k + 13, Block.planks.blockID, 3);
		world.setBlockAndMetadata(i + 12, j + 0, k + 14, Block.planks.blockID, 3);
		world.setBlockAndMetadata(i + 12, j + 0, k + 15, Block.planks.blockID, 3);
		world.setBlockAndMetadata(i + 12, j + 0, k + 16, Block.planks.blockID, 3);
		world.setBlock(i + 12, j + 0, k + 17, Block.dirt.blockID);
		world.setBlock(i + 12, j + 0, k + 18, Block.grass.blockID);
		world.setBlock(i + 12, j + 0, k + 19, Block.grass.blockID);
		world.setBlock(i + 12, j + 0, k + 20, Block.grass.blockID);
		world.setBlock(i + 12, j + 0, k + 21, Block.grass.blockID);
		world.setBlock(i + 12, j + 0, k + 22, Block.grass.blockID);
		world.setBlock(i + 12, j + 0, k + 23, Block.grass.blockID);
		world.setBlock(i + 12, j + 0, k + 24, Block.grass.blockID);
		world.setBlock(i + 12, j + 1, k + 1, Block.stoneBrick.blockID);
		world.setBlock(i + 12, j + 1, k + 17, Block.stoneBrick.blockID);
		world.setBlock(i + 12, j + 2, k + 1, Block.brick.blockID);
		world.setBlock(i + 12, j + 2, k + 17, Block.brick.blockID);
		world.setBlock(i + 12, j + 3, k + 1, Block.brick.blockID);
		world.setBlock(i + 12, j + 3, k + 17, Block.brick.blockID);
		world.setBlock(i + 12, j + 4, k + 1, Block.brick.blockID);
		world.setBlock(i + 12, j + 4, k + 15, Block.stoneBrick.blockID);
		world.setBlock(i + 12, j + 4, k + 16, Block.stoneBrick.blockID);
		world.setBlock(i + 12, j + 4, k + 17, Block.brick.blockID);
		world.setBlock(i + 12, j + 5, k + 1, Block.brick.blockID);
		world.setBlock(i + 12, j + 5, k + 17, Block.brick.blockID);
		world.setBlock(i + 12, j + 6, k + 1, Block.brick.blockID);
		world.setBlock(i + 12, j + 7, k + 1, Block.brick.blockID);
		world.setBlock(i + 12, j + 7, k + 17, Block.thinGlass.blockID);
		world.setBlock(i + 12, j + 8, k + 17, Block.brick.blockID);
		world.setBlock(i + 12, j + 9, k + 1, Block.brick.blockID);
		world.setBlock(i + 12, j + 9, k + 15, Block.brick.blockID);
		world.setBlock(i + 12, j + 9, k + 16, Block.brick.blockID);
		world.setBlock(i + 12, j + 9, k + 17, Block.brick.blockID);
		world.setBlock(i + 12, j + 10, k + 1, Block.brick.blockID);
		world.setBlock(i + 12, j + 10, k + 12, Block.brick.blockID);
		world.setBlock(i + 12, j + 10, k + 13, Block.brick.blockID);
		world.setBlock(i + 12, j + 10, k + 14, Block.brick.blockID);
		world.setBlock(i + 12, j + 10, k + 15, Block.stoneSingleSlab.blockID);
